Workbook
Name OLE_LINK10: '(参考)第1期中期小項目別評価'!#REF!
Name OLE_LINK10: '①業務実績報告書 (表紙～Ⅲ) '!#REF!
Name OLE_LINK10: ④小項目別評価!#REF!
Name OLE_LINK21: '(参考)第1期中期小項目別評価'!#REF!
Name OLE_LINK21: '①業務実績報告書 (表紙～Ⅲ) '!#REF!
Name OLE_LINK21: ④小項目別評価!#REF!
Name OLE_LINK26: '①業務実績報告書 (表紙～Ⅲ) '!#REF!
Name OLE_LINK26: ④小項目別評価!#REF!
Name OLE_LINK5: '(参考)第1期中期小項目別評価'!#REF!
Name OLE_LINK5: '①業務実績報告書 (表紙～Ⅲ) '!#REF!
Name OLE_LINK5: ④小項目別評価!#REF!
Name OLE_LINK66: '①業務実績報告書 (表紙～Ⅲ) '!#REF!
Name OLE_LINK66: ④小項目別評価!#REF!
Name OLE_LINK81: '①業務実績報告書 (表紙～Ⅲ) '!#REF!
Name OLE_LINK81: ④小項目別評価!#REF!
Name OLE_LINK82: '①業務実績報告書 (表紙～Ⅲ) '!#REF!
Name OLE_LINK82: ④小項目別評価!#REF!
Name OLE_LINK91: '①業務実績報告書 (表紙～Ⅲ) '!#REF!
Name OLE_LINK91: ④小項目別評価!#REF!

Sheet ①業務実績報告書 (表紙～Ⅲ) 
B11: 公立大学法人福知山公立大学
B14: 令和７事業年度及び中期目標期間（４年終了時）の | J14: ←〇〇事業年度の表記
B17: 業務実績報告書（案）
B36: 令和８年６月
J50: ←〇〇年度の表記
J60: ←〇〇年度の表記
B83: １ 基本情報（令和７年５月１日現在）
B84: （１）法人名 | D84: 公立大学法人福知山公立大学
B85: （２）所在地 | D85: 京都府福知山市字堀3370番地
B86: （３）設立団体 | D86: 福知山市
B87: （４）設立根拠法 | D87: 地方独立行政法人法
B88: （５）設立認可年月日 | D88: 平成27年11月24日
B89: （６）設立登記年月日 | D89: 平成28年４月１日
B90: （７）資本金 | D90: 1,562,130,000円（全額 福知山市出資）
B91: （８）理事長（代表者） | D91: 川添 信介
B93: （９）法人の目的 | D93: この公立大学法人は、教育のまち福知山における「学びの拠点」として、地方独立行政法人法に基づき、大学を設置し、及び管理することにより、総合的な知識と専門的な学術を深く教授研究するとともに、地域協働型教育研究を積極的に展開することにより、地域に根ざし、世界を視野に活躍できる高度な知識及び技能を有する人材を育成し、北近畿地域の持続可能な地域社会の形成と地方創生に寄与することを目的とする。
B96: （10）法人の業務 | D96: ア 公立大学を設置し、これを運営すること。 イ 学生に対し、修学、進路選択及び心身の健康等に関する相談その他の援助を行うこと。 ウ 法人以外の者から委託を受け、又はこれと共同して行う研究の実施その他の法人以外の者との連携による教育研究活動 を行うこと。 エ 地域の生涯学習の充実に資する多様な学習機会を提供すること。 オ 公立大学における教育研究成果の普及及び活用を通じ、地域社会及び国際社会に貢献すること。 カ 前各号の業務に附帯する業務を行うこと。
B98: （11）基本理念 | D98: 市民の大学、地域のための大学、世界とともに歩む大学
B100: ２ 設置する大学の学部・研究科の構成（令和７年５月１日現在）
B109: ３ 組織、運営体制 | E109: ５ 組織図（令和７年８月26日現在）
B110: （１）役員（令和７年４月１日現在）
B111: 理事長（学長） 川添 信介
B112: 理事（副学長） 西田 豊明
B113: 理事（副学長） 倉田 良樹
B114: 理事（非常勤） 柴田 洋三郎
B115: 理事（非常勤） 仁張 直敏
B116: 理事（非常勤） 三浦 和幸
B117: 監事（非常勤） 小嶋 勝
B118: 監事（非常勤） 西垣 秀照
B120: （２）専任教職員数（令和７年５月１日現在）
B121: 教員 教授 24人（地域経営学部12人、情報学部11人、
B122: 地域防災研究センター１人）
... B159: 法人による自己評価
B160: 令和７事業年度及び第２期中期目標期間（４年終了時）に係る業務実績報告書における自己評価は、以下の基準により実施する。 | J160: ←〇〇事業年度の表記
B161: ①小項目別評価
B162: 年度計画（中期計画）の記載項目（小項目）ごとの進捗状況の自己評価を行い、業務実績報告書において、次の４段階により進捗状況を示すとともに、
B163: 自己評価の判断理由（実施状況等）を記載する。
B165: ４･･･年度計画（中期計画）を上回って実施している（上回る実施状況）
B166: ３･･･年度計画（中期計画）を順調に実施している（十分な若しくは概ね実施）
B167: ２･･･年度計画（中期計画）を十分に実施できていない（下回る若しくは実施が不十分）
...

Sheet ③評価（年度）
D1: ３ 小項目別評価
D2: （１）令和７事業年度の業務の実績に係る自己評価結果一覧表
D3: 大項目番号 | E3: 項目 | J3: 項目数 | S3: 平均値
K4: 4 | M4: 3 | O4: 2 | Q4: 1
K6: 年度計画を上回って実施している（上回る実施状況） | M6: 年度計画を順調に実施している（十分な若しくは概ね実施） | O6: 年度計画を十分に実施できていない（下回る若しくは実施が不十分） | Q6: 年度計画を大幅に下回っている（特に劣る若しくは実施していない）
D7: 1 | E7: 第４－１ 教育に関する目標を達成するための措置 | J7: =SUM(K7:R7) -> 31 | K7: 3 | M7: 28 | O7: 0 | Q7: 0 | S7: =ROUND((K7*4+M7*3+O7*2+Q7*1)/J7,1) -> 3.1
K8: =ROUND(K7/$J$7,3) -> 0.097 | M8: =ROUND(M7/$J$7,3) -> 0.903 | O8: =ROUND(O7/$J$7,3) -> 0 | Q8: =ROUND(Q7/$J$7,3) -> 0 | U8: =SUM(K8:R8) -> 1
D9: 2 | E9: 第４－２ 研究に関する目標を達成するための措置 | J9: =SUM(K9:R9) -> 11 | K9: 2 | M9: 9 | O9: 0 | Q9: 0 | S9: =ROUND((K9*4+M9*3+O9*2+Q9*1)/J9,1) -> 3.2
K10: =ROUND(K9/$J$9,3) -> 0.182 | M10: =ROUND(M9/$J$9,3) -> 0.818 | O10: =ROUND(O9/$J$9,3) -> 0 | Q10: =ROUND(Q9/$J$9,3) -> 0 | U10: =SUM(K10:R10) -> 1
D11: 3 | E11: 第４－３ 地域・社会貢献に関する目標を達成するための措置 | J11: =SUM(K11:R11) -> 10 | K11: 6 | M11: 4 | O11: 0 | Q11: 0 | S11: =ROUND((K11*4+M11*3+O11*2+Q11*1)/J11,1) -> 3.6
K12: =ROUND(K11/$J$11,3) -> 0.6 | M12: =ROUND(M11/$J$11,3) -> 0.4 | O12: =ROUND(O11/$J$11,3) -> 0 | Q12: =ROUND(Q11/$J$11,3) -> 0 | U12: =SUM(K12:R12) -> 1
D13: 4 | E13: 第５ 業務運営の改善及び効率化に関する目標を達成するための措置 | J13: =SUM(K13:R13) -> 7 | K13: 0 | M13: 7 | O13: 0 | Q13: 0 | S13: =ROUND((K13*4+M13*3+O13*2+Q13*1)/J13,1) -> 3
K14: =ROUND(K13/$J$13,3) -> 0 | M14: =ROUND(M13/$J$13,3) -> 1 | O14: =ROUND(O13/$J$13,3) -> 0 | Q14: =ROUND(Q13/$J$13,3) -> 0 | U14: =SUM(K14:R14) -> 1
D15: 5 | E15: 第６ 財務内容の改善に関する目標を達成するための措置 | J15: =SUM(K15:R15) -> 6 | K15: 0 | M15: 6 | O15: 0 | Q15: 0 | S15: =ROUND((K15*4+M15*3+O15*2+Q15*1)/J15,1) -> 3
K16: =ROUND(K15/$J$15,3) -> 0 | M16: =ROUND(M15/$J$15,3) -> 1 | O16: =ROUND(O15/$J$15,3) -> 0 | Q16: =ROUND(Q15/$J$15,3) -> 0 | U16: =SUM(K16:R16) -> 1
D17: 6 | E17: 第７ 自己点検・評価及び当該状況に係る情報の提供に関する目標を達成するための措置 | J17: =SUM(K17:R17) -> 2 | K17: 0 | M17: 2 | O17: 0 | Q17: 0 | S17: =ROUND((K17*4+M17*3+O17*2+Q17*1)/J17,1) -> 3
K18: =ROUND(K17/$J$17,3) -> 0 | M18: =ROUND(M17/$J$17,3) -> 1 | O18: =ROUND(O17/$J$17,3) -> 0 | Q18: =ROUND(Q17/$J$17,3) -> 0 | U18: =SUM(K18:R18) -> 1
D19: 7 | E19: 第８ その他業務運営に関する重要目標を達成するための措置 | J19: =SUM(K19:R19) -> 13 | K19: 1 | M19: 12 | O19: 0 | Q19: 0 | S19: =ROUND((K19*4+M19*3+O19*2+Q19*1)/J19,1) -> 3.1
K20: =ROUND(K19/$J$19,3) -> 0.077 | M20: =ROUND(M19/$J$19,3) -> 0.923 | O20: =ROUND(O19/$J$19,3) -> 0 | Q20: =ROUND(Q19/$J$19,3) -> 0 | U20: =SUM(K20:R20) -> 1
E21: 合計 | J21: =SUM(J7:J20) -> 80 | K21: =SUM(K7,K9,K11,K13,K15,K17,K19) -> 12 | M21: =SUM(M7,M9,M11,M13,M15,M17,M19) -> 68 | O21: =SUM(O7,O9,O11,O13,O15,O17,O19) -> 0 | Q21: =SUM(Q7,Q9,Q11,Q13,Q15,Q17,Q19) -> 0 | S21: =ROUND((K21*4+M21*3+O21*2+Q21*1)/J21,1) -> 3.2
K22: =ROUND(K21/$J$21,3) -> 0.15 | M22: =ROUND(M21/$J$21,3) -> 0.85 | O22: =ROUND(O21/$J$21,3) -> 0 | Q22: =ROUND(Q21/$J$21,3) -> 0 | U22: =SUM(K22:R22) -> 1
F71: ・令和元年度の志願時のアンケートでは志願のきっかけとして「高校教員」と記入したのが回答者の60.8％であり、例年の傾向からは変化はなかった。情報学部では「塾・予備校講師からのすすめ」との回答が数件見られた。また、高校教員からは、特に都市部の高校は塾・予備校の進路指導の影響が強いとの意見が聞かれたため、塾・予備校に対する資料送付や訪問を新たに行った（塾・予備校への訪問実績：18件）。新型コロナウイルス感染症の影響により訪問が難しい状況の中で、20校程度を訪問することができた。 ・社会貢献や地域貢献を兼ねた教員による出張講義は34回行った。 ・在学生の母校訪問については、新型コロナウイルス感染症の影響を考慮して在学生を募っていない。 ・1年次生を対象として入学後の新入生アンケートを実施した。これにより、本学に入学した学生の受験動向を把握した。

Sheet ③評価（中期）
D1: ３ 小項目別評価
D2: （２）中期目標期間（４年終了時）の業務の実績に係る自己評価結果一覧表
D3: 大項目番号 | E3: 項目 | J3: 項目数 | S3: 平均値
K4: 4 | M4: 3 | O4: 2 | Q4: 1
K6: 中期計画を上回って実施している（上回る実施状況） | M6: 中期計画を順調に実施している（十分な若しくは概ね実施） | O6: 中期計画を十分に実施できていない（下回る若しくは実施が不十分） | Q6: 中期計画を大幅に下回っている（特に劣る若しくは実施していない）
D7: 1 | E7: 第４－１ 教育に関する目標を達成するための措置 | J7: =SUM(K7:R7) -> 32 | K7: 5 | M7: 27 | O7: 0 | Q7: 0 | S7: =ROUND((K7*4+M7*3+O7*2+Q7*1)/J7,1) -> 3.2
K8: =ROUND(K7/$J$7,3) -> 0.156 | M8: =ROUND(M7/$J$7,3) -> 0.844 | O8: =ROUND(O7/$J$7,3) -> 0 | Q8: =ROUND(Q7/$J$7,3) -> 0 | U8: =SUM(K8:R8) -> 1
D9: 2 | E9: 第４－２ 研究に関する目標を達成するための措置 | J9: =SUM(K9:R9) -> 11 | K9: 2 | M9: 9 | O9: 0 | Q9: 0 | S9: =ROUND((K9*4+M9*3+O9*2+Q9*1)/J9,1) -> 3.2
K10: =ROUND(K9/$J$9,3) -> 0.182 | M10: =ROUND(M9/$J$9,3) -> 0.818 | O10: =ROUND(O9/$J$9,3) -> 0 | Q10: =ROUND(Q9/$J$9,3) -> 0 | U10: =SUM(K10:R10) -> 1
D11: 3 | E11: 第４－３ 地域・社会貢献に関する目標を達成するための措置 | J11: =SUM(K11:R11) -> 10 | K11: 6 | M11: 4 | O11: 0 | Q11: 0 | S11: =ROUND((K11*4+M11*3+O11*2+Q11*1)/J11,1) -> 3.6
K12: =ROUND(K11/$J$11,3) -> 0.6 | M12: =ROUND(M11/$J$11,3) -> 0.4 | O12: =ROUND(O11/$J$11,3) -> 0 | Q12: =ROUND(Q11/$J$11,3) -> 0 | U12: =SUM(K12:R12) -> 1
D13: 4 | E13: 第５ 業務運営の改善及び効率化に関する目標を達成するための措置 | J13: =SUM(K13:R13) -> 7 | K13: 0 | M13: 7 | O13: 0 | Q13: 0 | S13: =ROUND((K13*4+M13*3+O13*2+Q13*1)/J13,1) -> 3
K14: =ROUND(K13/$J$13,3) -> 0 | M14: =ROUND(M13/$J$13,3) -> 1 | O14: =ROUND(O13/$J$13,3) -> 0 | Q14: =ROUND(Q13/$J$13,3) -> 0 | U14: =SUM(K14:R14) -> 1
D15: 5 | E15: 第６ 財務内容の改善に関する目標を達成するための措置 | J15: =SUM(K15:R15) -> 6 | K15: 0 | M15: 6 | O15: 0 | Q15: 0 | S15: =ROUND((K15*4+M15*3+O15*2+Q15*1)/J15,1) -> 3
K16: =ROUND(K15/$J$15,3) -> 0 | M16: =ROUND(M15/$J$15,3) -> 1 | O16: =ROUND(O15/$J$15,3) -> 0 | Q16: =ROUND(Q15/$J$15,3) -> 0 | U16: =SUM(K16:R16) -> 1
D17: 6 | E17: 第７ 自己点検・評価及び当該状況に係る情報の提供に関する目標を達成するための措置 | J17: =SUM(K17:R17) -> 2 | K17: 0 | M17: 2 | O17: 0 | Q17: 0 | S17: =ROUND((K17*4+M17*3+O17*2+Q17*1)/J17,1) -> 3
K18: =ROUND(K17/$J$17,3) -> 0 | M18: =ROUND(M17/$J$17,3) -> 1 | O18: =ROUND(O17/$J$17,3) -> 0 | Q18: =ROUND(Q17/$J$17,3) -> 0 | U18: =SUM(K18:R18) -> 1
D19: 7 | E19: 第８ その他業務運営に関する重要目標を達成するための措置 | J19: =SUM(K19:R19) -> 14 | K19: 0 | M19: 14 | O19: 0 | Q19: 0 | S19: =ROUND((K19*4+M19*3+O19*2+Q19*1)/J19,1) -> 3
K20: =ROUND(K19/$J$19,3) -> 0 | M20: =ROUND(M19/$J$19,3) -> 1 | O20: =ROUND(O19/$J$19,3) -> 0 | Q20: =ROUND(Q19/$J$19,3) -> 0 | U20: =SUM(K20:R20) -> 1
E21: 合計 | J21: =SUM(J7:J20) -> 82 | K21: =SUM(K7,K9,K11,K13,K15,K17,K19) -> 13 | M21: =SUM(M7,M9,M11,M13,M15,M17,M19) -> 69 | O21: =SUM(O7,O9,O11,O13,O15,O17,O19) -> 0 | Q21: =SUM(Q7,Q9,Q11,Q13,Q15,Q17,Q19) -> 0 | S21: =ROUND((K21*4+M21*3+O21*2+Q21*1)/J21,1) -> 3.2
K22: =ROUND(K21/$J$21,3) -> 0.159 | M22: =ROUND(M21/$J$21,3) -> 0.841 | O22: =ROUND(O21/$J$21,3) -> 0 | Q22: =ROUND(Q21/$J$21,3) -> 0 | U22: =SUM(K22:R22) -> 1
F71: ・令和元年度の志願時のアンケートでは志願のきっかけとして「高校教員」と記入したのが回答者の60.8％であり、例年の傾向からは変化はなかった。情報学部では「塾・予備校講師からのすすめ」との回答が数件見られた。また、高校教員からは、特に都市部の高校は塾・予備校の進路指導の影響が強いとの意見が聞かれたため、塾・予備校に対する資料送付や訪問を新たに行った（塾・予備校への訪問実績：18件）。新型コロナウイルス感染症の影響により訪問が難しい状況の中で、20校程度を訪問することができた。 ・社会貢献や地域貢献を兼ねた教員による出張講義は34回行った。 ・在学生の母校訪問については、新型コロナウイルス感染症の影響を考慮して在学生を募っていない。 ・1年次生を対象として入学後の新入生アンケートを実施した。これにより、本学に入学した学生の受験動向を把握した。

Sheet ④小項目別評価
B1: （２）小項目別業務実績・自己評価結果
B2: 項 目 別 の 状 況
B4: 第４－１ 教育に関する目標 | G4: ※「業務の実績」における下線部分は、特筆事項とする。
B5: （１）教育の成果
B7: 中 期 目 標 | D7: ディプロマポリシー（学位授与方針）に基づき、グローバルな視野に立ち、高い専門性と論理的・批判的思考力や表現力、コミュニケーション力、そして生涯にわたり学び続ける力を涵養する。
B9: 中期計画 年度計画 番号 | C9: 中期計画 | D9: 業務の実績（中期計画） | E9: 自己評価 | F9: 年度計画 | G9: 業務の実績 | H9: 自己評価
B11: 第４－１ 教育に関する目標を達成するための措置
B12: （１）教育の成果
B13: 1 | C13: ・本学が共通教育と専門教育の両方によって育成すべき人材像として掲げる「グローカリスト」が持つべき具体的な資質・能力を、両学部が掲げる「学修のアウトカム」と関連付けてより明確に提示し、ディプロマポリシーだけでなく、アドミッションポリシー、カリキュラムポリシーにも反映させる。 | D13: 【令和４年度～令和７年度の総括】 ・地域経営学部では、令和４年度及び令和５年度の入学者には令和２年度カリキュラム、令和６年度及び令和７年度の入学者には令和６年度カリキュラムで教育を実施した。また、情報学部は令和２年４月に設置され、令和５年度に最初の卒業者を送り出すとともに、この４年間のカリキュラムを見直した令和６年度カリキュラムを実施してきた。このように各学部において教育の実施やカリキュラムの見直しを進める一方で、令和６年度及び令和７年度において、全学的なカリキュラムの再検討が別途なされた。その結果、両学部ともに令和８年度入学者より、新たな令和８年度カリキュラムで教育を実施することとなった。 ・この全学的なカリキュラムの再検討にあたり、本学が育成すべき人材像として掲げる「グローカリスト」育成を発展・深化させることによって、令和８年度の学士課程教育改編で、「情報学を基盤とした地域協働型教育」及び「汎用的学修能力育成」を二つの教育の柱として定めた。具体的には、「グローバル」な能力を、単なる国際交流や国際的知見の獲得にとどまらず、広く地球社会一般に通用する知見の創出や技術・方法論の開発・適用能力として再定義し、これを「汎用的学修能力」として育成することとした。なお、この能力は中期目標が掲げる「生涯にわたり学び続ける力」の基礎ともなる。他方、「ローカル」の側面を、データに基づき地域の実態を把握し、課題解決に取り組む実践的能力と定義し、「情報学を基盤とした地域協働型教育」を通じて育成することとした。上記の二つの方針を、全学及び両学部の三つのポリシー並びにかつての「学修のアウトカム」に相当する「学年ごとの到達目標」に一貫性を持って反映させた。 ・令和８年度カリキュラムを作成するにあたり、両学部の新しい三つのポリシーを作成するとともに、大学全体の三つのポリシーも新たに作成した。さらに、令和８年度から実施するカリキュラムの具体的内容について検討し、カリキュラムマップやカリキュラムツリーを策定するとともに、各科目の具体的授業概要を作成した。 【令和８年度・令和９年度の見込】 ・両学部及び基盤教育院において、令和８年度から適用する新しい教育方針に基づくカリキュラムを実施する。 ・地域経営学部では、上記に加え、基盤教育科目の学修成果を各専門教育科目及び卒業研究につなげる仕組みを構築する。 ・情報学部では、令和５年度入学者に対するカリキュラム、令和６年度、令和７年度入学者向けカリキュラム、そして令和８年度以降の入学者向けカリキュラムと三つのカリキュラムが並行した教育となるが、令和８年度のカリキュラムは、これまでの経緯を踏まえ、本学におけるディプロマ・ポリシー、カリキュラム・ポリシーをより明確に反映した改革であり、また、実施に向けた検討、準備も十分になされていることから大きな混乱はないと思われる。 | E13: 3 | F13: ・地域経営学部及び情報学部では、令和８年度から適用する新しい教育方針に基づくカリキュラムの実施に向けた準備を進める。 ・令和６年度までの成績にもとづき、両学部が掲げる「学修のアウトカム」について、カリキュラムマップに従い学生の「外国語科目群」、「一般教養科目群」における履修申請率、修得率、成績分布の把握・測定を行う。 | G13: ・学士課程教育刷新により、「情報学を基盤とした地域協働型教育」と「汎用的学修能力の育成」を教育の柱とし、新たに大学全体及び両学部のディプロマ・ポリシー（学位授与方針）、カリキュラム・ポリシー（教育課程編成・実施方針）、アドミッション・ポリシー（入学者受入方針）を決定し、令和8年度から実施する新たなカリキュラムを制定した。新しいカリキュラムにおいては、両学部ともに４年間を通じた学修プロセスを見直し、主要科目の設定、指導教員制度の導入等、令和８年度からの新カリキュラム実施に向け、それぞれ検討を行い、両学部の教授会において、以下のように検討状況やカリキュラムマップ等の報告・審議を重ね、令和８年４月からの実施に向けた準備を完了した。 【地域経営学部】 ①９月教授会：令和８年度カリキュラムの主旨について学長からの説明があり意見交換会を実施（Slackにおいても継続） ②10月教授会：令和６年度カリキュラム科目と令和８年度カリキュラム科目の読み替えについて審議 ③11月教授会：令和８年開講科目、担当者一覧について審議 ④12月教授会：令和８年開講科目、担当者一覧について審議し、授業概要が執行会議で承認・確定したことを報告 ⑤１月教授会：令和８年度カリキュラムにおける卒業研究の履修条件等について審議 【情報学部】 ①５月教授会：情報学部カリキュラムＷＧの設置を報告 ②８月教授会：令和８年度以降入学者のカリキュラムマップ及びカリキュラムツリー、情報専門基礎科目群（いずれも案）を報告、意見聴取 ③９月教授会：令和8年度カリキュラムの主旨について学長からの説明があり意見交換会を実施（Slackにおいても継続） ④10月教授会：2026カリキュラム実施WGからの提案（ＩＴ実習などの実習・演習の担当について、卒業研究の研究室配属・異動について）（Slackにおいても継続して意見交換） ⑤Slack審議：令和６年度カリキュラム科目と令和８年度カリキュラム科目の読み替えについて審議 ⑥11月教授会：令和８年開講科目、担当者一覧について審議 ⑦12月教授会：授業概要が執行会議で承認・確定したことを報告 ⑧１月教授会：卒業研究科目の履修条件について審議 なお、２月から３月にかけては、両学部において４月からのカリキュラム実施に向けてガイダンス資料の作成、授業資料の作成など具体的作業を行った。 ・令和２年度から令和６年度までの入学者の「外国語科目群」及び「一般教養科目群」の科目毎、入学年度毎、学部・学科毎の履修申請率、修得率を計測して比較するとともに、成績分布について、大学全体を母集団とした適合度の検定を行い、科目毎、入学年度毎、学部・学科毎の傾向を把握した。その結果、必修科目は履修申請率・修得率ともに高く、選択科目では履修状況に差が見られた。また、成績分布については、多くの科目で科目群全体とは異なる傾向が確認された。 | H13: 3
B16: 第４－１ 教育に関する目標
B17: （２）教育内容
B19: 中 期 目 標 | D19: カリキュラムポリシー（教育課程編成方針）に基づき、文理双方の学部間連携など大学の強みを活かし、教養教育から専門教育まで実践的でグローカルな学部教育を展開するとともに、社会情勢や地域ニーズなどを踏まえ、学部学科編成の最適化に取り組む。 また令和６年度を目処に、情報学部を中軸とした文理連携による地域協働型教育研究を展開するための新たな拠点となる大学院を設置して地域の発展を牽引する高度なＩＣＴ人材を育成する。
B21: 中期計画 年度計画 番号 | C21: 中期計画 | D21: 業務の実績（中期計画） | E21: 自己評価 | F21: 年度計画 | G21: 業務の実績 | H21: 自己評価
B23: 第４－１ 教育に関する目標を達成するための措置
B24: （２）教育内容
B25: 2 | C25: ①教育課程の編成
C26: ・地域経営学部については、「地域経営」の概念を整理して、「地域についての体系的な学修」ができるよう、教育内容の改善を行う。また、令和６年度に情報学部と共同で新たに設置を目指す大学院修士課程を視野に入れて、開講科目の再編成を行うとともに、これに合わせて教員組織のあり方を改善する。 | D26: 【令和４年度～令和７年度の総括】 ・地域経営学部では、学際的な特徴をもつ地域経営を公共経営、企業経営、交流観光、医療福祉経営という４系統から構成されるものとして概念を整理した。令和６年度から新たなカリキュラムを実施し、学部専門教育を４系統に沿って年次ごとに科目を配当している。系統ごとにカリキュラムマップとカリキュラムツリーを作成・公表し、学生の履修指導などにおいて活用することで地域経営の体系的な学修ができるよう、教育内容の改善を行った。大学院修士課程との接続を視野に入れた教育課程の具体的な編成内容については、大学院で開講される４科目（公共ガバナンス論、ベンチャー・アントレプレナーシップ論、経営学特論、地域福祉政策論）に接続する６科目（ガバナンス論、地域ベンチャー育成論（令和６年度カリキュラムにおけるベンチャー企業論）、経営組織論、人的資源管理論、介護福祉論（令和６年度カリキュラムにおける高齢者福祉論）、地域福祉論）を学部専門教育科目に設置した。また、令和６年度に設置した地域経営学部執行会議が、ディプロマ・ポリシー第５項に示した学修目標を達成するための授業の成果について、系統を展開する各学科及び学部全体の教学アセスメントを実施することで、教学マネジメントにおける組織的な対応力を強化した。 【令和８年度・令和９年度の見込】 ・令和６年度及び令和７年度に入学した学生に対し、ディプロマ・ポリシー及びカリキュラム・ポリシーに基づき、令和６年度カリキュラムの教育を実施する。 | E26: 3 | F26: ・地域経営学部では、学部専門教育を公共経営、企業経営、交流観光、医療福祉経営という４系統に沿って展開し、地域経営の体系的な学修を実現する。教員組織もこの４系統と対応する形で運営し、教学における組織的な対応力を強化する。 ・地域経営学部教員は、大学院では学部専門教育を深化・発展させた社会科学系科目と文理融合科目を担当し、学生が「地域社会に情報技術を還元するための実践活動に資する知識」を獲得できるようにする。 | G26: ・令和６年度から新たなカリキュラムを実施し、専門教育を４系統に沿って「学びを始める（初年次）」「学びを広げる（２年次）」「学びを深める（３年次）」「学びをまとめる（４年次）」という学年ごとの編成方針に基づき科目を配当している。これにより、座学による知識の伝授と地域現場における「地域協働型教育」を組み合わせることによって体系的な学修を実現するとともに、系統ごとにカリキュラムマップとカリキュラムツリーを作成・公表し、学生の履修指導などにおいて活用することで地域経営の体系的な学修を推進した。また、学部の教学について検討する目的で設置した地域経営学部執行会議の組織により、ディプロマポリシー第5項に示した学修目標を達成するための授業成果について、系統を展開する各学科及び学部全体の教学アセスメントを実施し、教学マネジメントにおける組織的な対応力を強化した。 ・地域経営学部では学士課程教育改編に伴い、令和８年度からさらに新しいカリキュラムによる教育を実施することになった。令和８年度以降の開講に向けて以下の点を中心に準備を進め、令和８年４月からの開講準備が整った。 ①科目担当者の割り当て（令和６年度カリキュラム科目担当とのすり合わせ） ②専門教育科目の科目群概要、科目概要、到達目標の確定 ③カリキュラムマップ・カリキュラムツリーの作成 ④令和８年度カリキュラムの令和６年度カリキュラム科目への読み替え ⑤担任制度及び指導教員制度の設計 ⑥卒業研究の評価の検討 ⑦令和８年度カリキュラムにおける「卒業研究Ⅰ～Ⅳ」の履修条件の設定 ⑧科目履修例（履修モデル）の設計 ⑨履修申請単位数の上限に含まれない科目や他学部学生による履修申請を認めない科目の設定 ・地域経営学部は、大学院地域情報学研究科において、地域社会に情報技術を還元するための実践活動に資する知識を修得するために配置している「文理融合科目」と「社会科学系科目」の科目担当および修士課程指導教員として新たに２人、兼任教員として配置した。 | H26: 3
B27: 3 | C27: ・情報学部については、令和５年度に完成年次を迎えることと令和６年度に地域経営学部と共同で設置する新たな大学院修士課程の設置予定を視野に入れて、令和６年度以降のカリキュラムポリシーを更新し、それに基づく教育課程の編成等を図る。 | D27: 【令和４年度～令和７年度の総括】 ・情報学部では、令和５年度に完成年次を迎え、令和６年度に地域経営学部と共同で設置する新たな大学院修士課程を設置した。大学院設置にあわせて令和６年度以降のカリキュラム・ポリシーを更新し、それに基づく教育課程を再編した。この見直しにおいては、４年間の実績を踏まえ、基礎技術力の充実と大学院の教育を見据えた専門知識、学修成果の向上を図ることをめざすものとし、以下のカリキュラム・ポリシーに変更した。 (カリキュラム・ポリシー) 下記の 4 つの側面からカリキュラムを編成し、座学と実践的学修を充実し、学修成果の向上を図る。 1. 帰納的な教育と実践的な学修を中心としたカリキュラムを編成する。本学の「地域協働型教育研究」を具体化した、プロジェクトベースの演習系科目等を配置し、地域社会における実践につながる教育を展開する。 2. 情報学の体系・知識・知見・技術を学びつつ、現場に応用・活用する「知」の総合化を図ることのできるカリキュラムを編成する。地域社会のさまざまな様相を理解し、社会に貢献できる人材を育成するために、地域関連科目を配置する。 3. 段階的に専門的な原理に近づいていくカリキュラムを編成する。専門科目を実践系科目、基盤系科目、理論系科目に分類するとともに実践から理論へと進む流れを基本とする。個々の概念間の関係や当該事例の中での位置づけを強く意識させることにより、堅固な基礎学力の獲得を図る。さらに、演習系科目である「プログラミング演習」「ＩＴ 実習」を１、２年次に配置し、基本技術力の獲得を図る。 4. 専門領域の知識習得、学修成果の向上を図るカリキュラムを編成する。数理・データサイエンス（データ解析やその活用について専門的に学習するトラック）、ＩＣＴ（情報システムの構築について専門的に学習するトラック）、人間・社会情報学（人間・社会が関わる様々な領域における情報技術について専門的に学習するトラック）を設ける。トラック別に高度な知識や知見を修得し、現場対応力の高い人材を育てる科目を配置する。 さらに、令和８年度からの全学的な学士教育課程改編に基づき、地域経営学部及び新たに設置される基盤教育院と連携した学部教育の実施を以下のような形で具現化した。 1. 基盤教育科目における「情報と社会」、「データサイエンス」などの両学の学生が共通に履修する情報科目群の設定 2. 「アカデミックリーディング」、「哲学」などの汎用的学修能力を育成するための基礎科目群の設定 3. 両学部の学生が同じグループで学びを進める地域協働演習の開講 【令和８年度・令和９年度の見込】 ・令和８年度は三つの異なる教育課程を並行して進めることとなったが、新たな教育課程は本学のディプロマ・ポリシー、カリキュラム・ポリシーをより明確に実装したものであり、また、その実施に向けての準備も順調に進められてきたことから、大きな混乱はないと考える。今後２年間についても、実施状況を詳細にチェックしていくことが重要と考える。 | E27: 3 | F27: 情報学部では、令和６年度開始のカリキュラムの実施状況を踏まえ、令和８年度開始のカリキュラムの開講準備を整える。 | G27: 情報学部では、令和５年度に完成年次を迎えてカリキュラムを再検討し、令和６年度から新しいカリキュラムでの教育を実施してきた。一方、学士課程教育改編に伴い、令和８年度からさらに新しいカリキュラムによる教育を実施することになった。令和６年度カリキュラムを進めながら、令和８年度からの新しいカリキュラム実施にむけてワーキンググループを設置し、開講準備を進めた。 ワーキンググループでは、令和８年度以降の開講に向けて以下の点を中心に準備を進め、令和８年４月からの開講準備が整った。 ①科目担当者の割り当て（令和６年度カリキュラム科目担当とのすり合わせ） ②専門教育科目の科目群概要、科目概要、到達目標の確定 ③カリキュラムマップ・カリキュラムツリーの作成 ④令和８年度カリキュラムの令和６年度カリキュラム科目への読み替え ⑤令和８年度カリキュラムにおける「卒業研究Ⅰ～Ⅳ」の履修条件の設定 ⑥科目履修例（履修モデル）の設計 ⑦履修申請単位数の上限に含まれない科目や他学部学生による履修申請を認めない科目の設定 | H27: 3
B29: 4 | C29: ・全学委員会としての教務委員会において、本学の２学部体制の利点を活かすために、大学院の設置をも視野に入れつつ、文理両分野にまたがる学修が可能となるように共通教育を再編成する。 | D29: 【令和４年度～令和７年度の総括】 ・令和６年度に情報学の深化をめざす研究開発に加え、その成果を地域にねざした実践活動に適用することをめざす大学院地域情報学研究科を設置した。また、学部においては、文理両分野にまたがる学修が可能となるよう令和８年度より共通教育を再編成し、新たに設置した基盤教育院による基盤教育科目を展開した。 ・両学部の学生が共に学ぶ基盤教育科目と各学部で展開する専門教育科目からなる令和８年度カリキュラムを策定するとともに、基盤教育科目の展開を担う基盤教育院の設計を行った。 将来にわたり多様な分野及び地域課題について広くかつ深く学び続ける力を学部横断的に育成することを目的とする基盤教育科目を編成し、その中の「地域協働基盤科目群」において、統計データの基本的な処理・分析力を身につけたうえで、地域が抱える具体的な課題を材料として地域協働の基本を学修する「地域協働演習」を、両学部１年次の必修科目として配置した。また、現代社会で活躍するために必要な情報学の基本的知識及びスキルを身につけることを目的として、「情報科目群」に両学部１年次の必修科目として「情報と社会」を配置するとともに、「データサイエンス」や「統計学Ⅰ」等の必履修科目を配置した。 両学部の学生が「論理的に考え表現する力」を身につけることを目的として、「論理学」や「数学的思考法演習」「論理的思考法演習」等の科目を基盤教育科目に配置した。 【令和８年度・令和９年度の見込】 ・令和８年度に設置された基盤教育院において、同年度から適用する新しい教育方針に基づくカリキュラムのもと、情報学部及び地域経営学部の学生を対象とした基盤教育科目を展開し、文理両分野にまたがる新たな教育を実施する。 | E29: 3 | F29: ・令和６年度までの成績にもとづき、全学共通科目群に配置されている両学部から提供されている科目について、履修申請率、修得率、成績分布の把握・測定を行う。 ・令和８年度カリキュラムにおいて、両学部の学生が共に学ぶ基盤教育を担う「基盤教育院」を整備し、具体的教育内容を検討する。 | G29: ・令和２年度から令和６年度までの入学者の「全学共通科目群」の科目毎、入学年度毎、学部・学科毎の履修申請率、修得率を計測して比較するとともに、成績分布について、大学全体を母集団とした適合度の検定を行い、科目毎、入学年度毎、学部・学科毎の傾向を把握した。その結果、令和２年度カリキュラムでは一部の３年次配当科目及び夏期集中講義で履修申請率・修得率が低い傾向が見られた。一方、令和６年度カリキュラムでは履修状況が極端に低い科目はなかった。また、成績分布は、両カリキュラムとも多くの科目で科目群全体とは異なる傾向を示した。 ・令和８年度カリキュラムにおいて、両学部の学生が共に学ぶ基盤教育科目を編成し、基盤教育を担う基盤教育院の設計を行った。令和８年度カリキュラムにおける「情報学を基盤とした地域協働型教育」と「汎用的学修能力の育成」の２つの教育目標のうち、「情報学を基盤とした地域協働型教育」の出発点となる講義科目「地域協働論」及び両学部が全員で共に学ぶ演習科目「地域協働演習」を１年次の必修科目として配置するとともに、それらを中心として、将来にわたり多様な分野及び地域課題について広くかつ深く学び続ける力を学部横断的に育成することを目的とする基盤教育科目の編成を行った。「地域協働演習」の設計にあたっては、専門委員会を立ち上げ、当該演習で扱うテーマの詳細や外部組織との連携等に関する調整を行った。また、基盤教育の質的向上及び充実を図る中心的な役割を担う「基盤教育院」を設置するに当たり、基盤教育院設置準備委員会を立ち上げ、基盤教育院の所属教員や所掌事項、基盤教育院教授会の運営方法等を定めた。 | H29: 3
B30: 5 | C30: ・共通教育と専門教育の両方にわたって、学生が「何を学び、何を身につけることができたのか」を意識し、理解できるような教育課程を編成する。 | D30: 【令和４年度～令和７年度の総括】 ・令和８年度カリキュラムを編成する際、共通教育を基盤教育として再編成し、専門教育といかに連携するかを検討するうえで、学生が「何を学び、何を身につけることができたのか」を意識し、理解できるような令和８年度カリキュラムを編成した。 ・令和８年度カリキュラムについて、基盤教育科目と専門教育科目からなるカリキュラムマップ及びカリキュラムツリーを作成し、学士課程教育の到達目標を明確に定めた。学士課程教育刷新委員会の下に地域経営学部カリキュラム検討ワーキンググループ（ＷＧ）を設置し、地域経営学部の専門教育科目の編成を行うとともに、その内容に基づきカリキュラムマップ及びカリキュラムツリーを策定し、学生が自らの学びの流れと目標を明確に理解し意識できるようにした。また、情報学部に設置された情報学部カリキュラム検討ワーキンググループ（ＷＧ）においても、同様に専門教育科目の編成を行い、その内容に基づき情報学部のカリキュラムマップ及びカリキュラムツリーを策定した。さらに、両学部の学生が共に学ぶ基盤教育科目と各学部で展開する専門教育科目からなる令和８年度カリキュラムを策定するとともに、基盤教育科目の展開を担う基盤教育院の設置を執行会議において、決定した。 【令和８年度・令和９年度の見込】 ・両学部の令和８年度カリキュラムにおける基盤教育科目と専門教育科目との関係性を検証するため、必要な教学データの項目や検証方法を検討し、教学データの取得及び蓄積を進める。 | E30: 4 | F30: ・共通教育と専門教育の両方にわたって、学生が「何を学び、何を身につけることができたのか」を意識し、理解できるような教育課程を編成するために、令和６年度の成績をもとに、令和６年度開講科目の履修申請率、修得率、成績分布の把握・測定を行う。 ・令和８年度カリキュラムにおいて両学部の学生が共に学ぶ基盤教育と各学部の専門教育から構成される学士課程教育の到達目標を各学部と調整しながら検討する。 | G30: ・令和６年度開講科目について、科目毎の履修申請率、修得率を計測して比較するとともに、成績分布について、大学全体を母集団とした適合度の検定を行い、科目毎の傾向を把握した。履修申請率及び修得率に科目間で大きなばらつきが見られた。成績分布については、科目全体と同様の傾向は示されなかった。 ・基盤教育と専門教育からなる令和８年度カリキュラムについて、体系的な教育課程を明確化するため、学修成果の達成にどの授業科⽬が寄与するかを⽰したカリキュラムマップ及び学修成果の達成に向けてどのような授業科⽬が連携し年次配当しているかを⽰したカリキュラムツリーを両学部において策定した。また、大学全体として、「情報学を基盤とした地域協働型教育」を通して、地域のさまざまな人々と協働し、情報学の知識と技術を地域の課題解決に向けて応用する力を身につけるとともに、「汎用的学修能力の育成」をふまえた教育を通して、多様に変化する社会の諸相について生涯にわたって学び、主体的に考え続ける力を修得し、新たな価値の創造や地域社会の発展に活かす能力を身に付けることを、学士課程教育の到達目標として策定した。 | H30: 4
B31: 6 | C31: ②教育職員免許状の課程の設置
C32: ・高等学校教育職員免許の情報の取得課程を設置する。 | D32: 【令和４年度～令和７年度の総括】 ・令和６年度末に高等学校教諭一種免許状（情報）、高等学校教諭一種免許状（数学）及び中学校教諭一種免許状（数学）の課程申請を提出し、令和７年12月に認定を受けた。 【令和８年度・令和９年度の見込】 ・令和８年度から教職課程を開始する。 入学時に教職課程履修の手引き（電子版）を配布し、学生向けガイダンスを実施するなど、教員免許を希望する学生の履修のための環境を整えていく。 今後、予定されている対象教科（中学校の数学、高等学校の数学及び情報）の指導要領の改訂の方向性を調査するほか、再課程認定に向けた準備を開始する。 | E32: 3 | F32: ・設置申請の内容について指摘事項があった場合に早急な対応ができるように準備を行う。 ・教職課程を実施するために必要な以下の項目等の準備を行う。 ①令和８年度入学生向けの「教職課程の手引き」を作成する ②履修者確保の観点から、高等学校向けの広報活動に協力する ③教職課程運営体制の検討を引き続き行う ④教職課程において必要な設備等の整備を行う ⑤採用試験対策をはじめとする学習支援の体制を計画する | G32: ・令和６年度末に文部科学省へ提出した設置申請書に対して、２度の審査意見が付されたが、その都度、迅速かつ適切な対応を行い、12月に高等学校教諭一種免許状（情報）、高等学校教諭一種免許状（数学）及び中学校教諭一種免許状（数学）の課程認定を受けた。 ・計画の各項目に対して、以下の通り準備作業を行った。 ①教職課程履修の手引きを作成し、情報学部の１年生向けに配布できるようにした。 ②高校訪問用に教職課程の履修に関するチラシを作成した。 ③令和８年度から教職課程運営委員会が活動できる体制を整え、新入生向けオリエンテーションでの説明等が実施できるようにした。 ④書籍を中心とした必要な設備等の整備を行った。 ⑤数理・データサイエンスセンターと協力して学習支援を行うことを検討した。 ⑥採用前倒しなど、教職採用の動向調査を行った。 | H32: 3
B33: 7 | C33: ・高等学校教育職員免許の数学と公民の取得課程の設置を目指した検討を行う。 | D33: 【令和４年度～令和７年度の総括】 ・令和６年度に教職課程準備委員会が発足するにあたり、事前のワーキンググループの検討に基づき、情報学部では高等学校教諭一種免許状（数学）に加え中学校教諭一種免許状（数学）の課程の設置をめざすことが確認された。 教職課程準備委員会では本検討結果に基づき、中学校及び高等学校の数学科の免許に必要な教職課程専任教員の構成を定め、数学科に関する専門的事項並びに教科教育法をカバーする科目群を設定することで、数学科の教職課程の認定を受けた。この点は計画を上回って実施できたと判断できる。 ・また、地域経営学部の検討により、高等学校の公民科の免許のための課程申請は行わないことを確認した。なお、公民科の課程申請を見送る主な理由は以下の２点である。 ①公民科の免許は教員採用試験の受験資格を満たすが、採用枠は地歴と公民がまとめられていることが一般的であり、採用試験でも両者が出題される傾向がある。このため、公民単独の免許の発行では実際に教職に就く教員養成には結びつきにくいこと。 ②地歴の教職課程を地域経営学科におくためには、さらに３人の科目適合性が認められる教職専任教員を配置する必要があるなど、現在の地域経営学科の教員配置では困難が予想されること。 これらにより、本計画は完了となった。 【令和８年度・令和９年度の見込】 ・計画完了につき、今後２年間の実施内容は計画番号６に統合される。 | E33: 4 | F33: ・対応済み。 | G33: ・対応済み。 | H33: 3
B34: 8 | C34: ③新しい大学院の設置
C35: ・情報学を中軸にしつつ地域経営学関連分野とも密接に連携する地域協働型教育研究を本学全体として展開するために、新たに大学院修士課程を、令和６年度を目途に設置する。 | D35: 【令和４年度～令和７年度の総括】 ・大学院の設置を令和６年度に完了し、順調に教育研究を進めている。本学大学院地域情報学研究科は、中期計画がめざしたように、情報学の深化とともに地域にねざした実践的な成果によって学位を認定することができるカリキュラム及び学位認定を行う研究科として令和６年度（第２期中期計画２年目）に設置された。 ・設置後２年間は設置申請書に記載された内容を適切に履行することを目標として、アドミッション（入学者選抜）～ディプロマ（学位授与）までの一連の事項を適正に実施した。当該期間中に実施された文部科学省による年次の審査において改善等を指示する意見を付されることはなく、適正な実施が行われたことが認められている（第２期中期計画３年目～４年目）。 設置開始から２年間は定員を充足できていない状況であった（１年目：15人、２年目：16人）が、大学院のことが学生に定着しつつある３年目では21人の入学者を確保し（合格者24人）、定員充足にも一定の目途がついたと考えられる。 ・さらに、大学院を取り巻く状況の変化と、入学者の確実な確保をめざして、設置から２年間（第２期中期計画３年目～４年目））に以下の取組みを実施した。 ①社会人入学者向け制度の整備（長期履修制度・入学者選抜における口頭試問免除制度・厚生労働省 教育訓練給付制度） ②主に内部学生向けの広報の取組み（学務ガイダンス・キャリアガイダンス・保護者向け講演） ③学外の大学生向け広報の取組み（大和大学） ④学部改編と並走して、カリキュラムの改善及び教員負荷低減のための大学院カリキュラム再編（令和８年度より実施分） 【令和８年度・令和９年度の見込】 ・大学を取り巻く状況に対応し、また教員負荷にも留意しつつ大学院修士課程の安定的な学生確保及びカリキュラム実施を継続する。 | E35: 3 | F35: ・設置認可申請書に定めたカリキュラム・ポリシーに従って、情報学を中軸にしつつ地域経営学関連分野（および文理融合分野）と密接に連携する教育カリキュラム（２年目）を実施する。 ・２年間の状況を踏まえ、大学院の今後のあり方を議論する。 | G35: ・設置認可申請書に定めたカリキュラム・ポリシーに従って、２年目の教育カリキュラムを滞りなく実施し、第１期入学者全員を修了させた。 ・大学院地域情報学研究科の２年間の教育実施状況を踏まえ、開講時期を適正に改善し、工学者倫理科目を独立科目として開講するなど、研究及びプロジェクト活動に寄り添った教育カリキュラムへの改善を検討し、令和８年度から実施することを決定した。 | H35: 3
B36: 9 | C36: ・大学院の博士課程設置に向けた方針を定める。 | D36: 【令和４年度～令和７年度の総括】 ・大学周辺を取り巻く状況を鑑み、以下の理由から喫緊での博士後期課程の設置は必要でないと判断した。 ①ここまでに入学した大学院生に、定員を適切に設置し、充足するほどの進学希望者が現れていないこと。（実績的にも学年に１人ないし２人の学生が進学又は進学を希望するにとどまっている。また、大学院博士後期課程の多くは研究科に３名以上の定員を定めている。） ②地域からの要望が仄聞されないこと。 加えて、博士課程の担当教員として適格と判定された教員の確保に代表される教育体制が整備されていないことも勘案し、十分な準備期間を欠いた性急な設置は期待される効果が得られないと判断したものである。 【令和８年度・令和９年度の見込】 ・今後の地域及び大学を取り巻く環境の変化に遅れることなく、博士後期課程設置の是非について調査検討と議論を継続する。 | E36: 3 | F36: ・大学院の今後のあり方を議論し、それに沿って、博士課程の設置の必要性が明らかになった際に改めて設置に関する議論を行う。 | G36: ・学生の進学希望状況及び現状の教員組織を踏まえ、喫緊での博士後期課程の設置の必要性はないと判断した。一方で、修了生に博士後期課程進学者がいること、博士後期課程進学希望学生が在学していることなどから、今後の設置の必要性については継続的に議論が必要であることも再確認した。 | H36: 3
B38: 第４－１ 教育に関する目標
B39: （３）地域協働型の教育の深化・充実
B41: 中 期 目 標 | D41: 持続可能な地域づくりに取り組む人材を育成する「福知山モデル」の具現化に向け、文理連携により、地域の課題や資源を教育に活かす仕組みを構築するとともに、フィールドワークや演習等の実践的な教育を充実する。
B43: 中期計画 年度計画 番号 | C43: 中期計画 | D43: 業務の実績（中期計画） | E43: 自己評価 | F43: 年度計画 | G43: 業務の実績 | H43: 自己評価
B45: 第４－１ 教育に関する目標を達成するための措置
B46: （３）地域協働型の教育の深化・充実
B47: 10 | C47: ①本学の特色である「地域協働型教育研究」の深化・充実
C48: ・「地域協働型教育」の深化・充実を図るために、地域経営学部ではフィールドワーク型演習系科目、情報学部ではＰＢＬ等の演習・実習科目の具体的な実態を把握しその学修成果を検討するための組織を両学部に設置する。 | D48: 【令和４年度～令和７年度の総括】 ・地域経営学部では、令和６年度に地域経営学部執行会議を設置し、実践教育実習費を活用したメディアセンターの一部改修及びメディアセンターによる紙媒体で現存する地域資料のデジタル化を教授会に提案・実施して、フィールドワーク型演習系科目の運営支援機能の強化を図った。 毎年度、フィールドワーク型演習系科目の学修成果を「地域協働型教育研究報告書」にまとめると同時に、例年２月に報告会を開催している。これらを通じて、当該科目の具体的な実態を把握し、学内外からの意見等を学修成果の改善に活かしてきた。 また、令和８年度カリキュラムにおいて、地域協働型教育の理論と実践を行う基盤教育科目として地域協働演習が開講される。地域協働演習の各クラス（チーム）は両学部の学生から構成され、科目担当者である地域経営学部、情報学部及び基盤教育院の教員は、学修成果の向上を図るために連携し、科目運営を実施する。 ・情報学部では、４年間で継続的に地域協働型教育、研究活動を実施してきた。特に、ＰＢＬ並びに近隣団体、地元高校と連携した活動の実態を学部内で把握、共有し、これらの活動の推進、拡大を図ってきた。具体的なテーマとして、 ①ジュニアＩＣＴ教室（福知山市、朝来市、丹波市との連携事業） ②ジュニアデジタルアカデミー（伊根町との連携事業） ③シニアワークカレッジ（福知山市との連携事業） ④消防活動におけるＡＩ支援（福知山市との連携事業） ⑤冠島オオミズナギドリの生態調査（京都府立西舞鶴高等学校との連携事業） ⑥音楽と情報技術をテーマとするインタラクティブ作品製作（みすずフェスタ、ＤＸでつながるワトクの学び、音のとびらを開く会inふくくるさんぽ） ⑦大江山パワーロード観光ガイド（京都未来人材育成プロジェクト） ⑧夜久野ウルシ苗木の根系解析（ＮＰＯ法人丹波漆との連携事業、京都未来人材育成プロジェクト） ⑨トレンドワードを用いた地域ＰＲ動画自動生成について ⑩飲食店におけるロボット・アバター連携による接客演出の効果 などが挙げられる。中期計画においては「学修成果を検討するための組織を両学部に設置する。」となっているが、現状では北近畿地域連携機構、学部長を中心に近隣団体、高校との要望に応じて、担当可能な教員を選考し、対応している状況である。中期計画後半では、これまで実施されたプロジェクトを中心に学修成果を検討する組織を設置し、評価を進めていく。 【令和８年度・令和９年度の見込】 ・１学年に両学部で連携した地域協働型教育プログラムとして、地域協働演習が設定されたことから、両学部及び基盤教育院と連携した地域協働型教育・研究の展開が見込める。 また、情報学部では、中期計画後半において、中間報告までに実施されたプロジェクトを中心に学修成果を検討する組織を設置し、評価を進めていく。 | E48: 3 | F48: ・地域経営学部では、地域協働型教育研究を推進するため、地域経営学部執行会議の活動を継続・強化し、フィールドワーク型演習系科目の効果的な運営を支え、授業内容の改善に関して教授会に提案する。 ・情報学部では大学院と連携した地域協働型教育研究を進める。 | G48: ・地域経営学部執行会議が教授会に提案し、実践教育実習費を活用してメディアセンターによる紙媒体の地域資料のデジタル化を行うことで、フィールドワーク型演習系科目の運営支援機能の強化を図った。 ・大学院生を含む地域協働型教育及び研究活動を積極的に実施された。具体的には、以下のようなテーマが大学院と連携した地域協働型研究として今年度に実施した。 ①消防活動におけるAI支援の研究 ②冠島オオミズナギドリの生態調査 ③Quality-Diversityに基づく多様な構造を持つ最適化問題の研究 ④飲食店におけるロボット・アバター連携による接客演出の効果 | H48: 3
B50: 11 | C50: ・共通教育については、教務委員会において、地域課題の解決や地域資源の活用に資する文理両分野にまたがる科目設定を図る。 | D50: 【令和４年度～令和７年度の総括】 ・令和８年度カリキュラムにおいて、共通教育は基盤教育として再編成し、新たに基盤教育院を設置した。基盤教育では、地域協働論、地域協働演習等の科目設定を行い、地域課題の解決や地域資源の活用に資する文理両分野にまたがる科目を設定した。 【令和８年度・令和９年度の見込】 ・令和８年度に設置された基盤教育院において、同年度から適用する新しい教育方針に基づくカリキュラムのもと、「地域協働基盤科目群」及び「情報科目群」を展開し、情報学部及び地域経営学部の学生を対象とした「情報学を基盤とした地域協働型教育」に取り組む。 | E50: 3 | F50: ・令和６年度までの成績にもとづき、全学共通科目群に配置された地域課題の解決に関する科目、地域資源の活用に資する科目について、履修申請率、修得率、成績分布の把握・測定を行う。 | G50: ・令和２年度から令和６年度までの入学者の全学共通科目群に配置された地域課題の解決に関する科目、地域資源の活用に資する科目について、科目毎、入学年度毎、学部・学科毎の履修申請率、修得率を計測して比較するとともに、成績分布について、大学全体を母集団とした適合度の検定を行い、科目毎、入学年度毎、学部・学科毎の傾向を把握した。その結果、令和２年度カリキュラムでは一部の３年次配当科目で履修申請率及び修得率が低く、成績分布も科目全体とは異なる傾向が見られた。一方、令和６年度カリキュラムでは履修状況は極端に低い科目はなく、成績分布も科目全体と同様の傾向を示した。 | H50: 3
B51: 12 | C51: ②インターンシップの充実
C52: ・地域協働の実践を経験しつつ、学生が自らのキャリアを考えるためのインターンシップを充実させる。 | D52: 【令和４年度～令和７年度の総括】 ・令和５年度の文部科学省・厚生労働省・経済産業省の合意による「インターンシップの推進に当たっての基本的考え方」の改正においては、常に就活市場の動向を注視し、学内ガイダンスで学生に周知するなど、前向きにインターンシップに参加できるよう支援を行った。また、学生だけではなく企業へのアプローチを強化し、インターンシッププログラムの充実に努めた。特に、令和５年度が初めての参加となった情報学部においては、より専門的な就業体験の場となるよう、学部限定のプログラム提供を企業に依頼し、プログラムの充実に努めた。 ・地域経営学部では、北近畿地域における事業所での実習経験を通じ、学生が北近畿地域の課題についての理解と、卒業後の進路を含む自身のキャリアについての考えを深めるため、「地域キャリア実習Ⅰ、Ⅱ」を実施し、受講を推奨してきた。インターンシップへ参加を希望する学生は、本学が提示する「地域キャリア実習 実習先リスト」に掲載された事業所の各実習内容から実習先を選定し、長期休暇期間などを活用して実習に参加している。 インターンシップの受入事業所は、北近畿地域の官公庁（市役所、警察署）、民間企業（製造業、運輸業、観光サービス、高齢者福祉施設等）である。 「地域キャリア実習Ⅰ、Ⅱ」では、実習後に学内で実施する報告会においてインターンシップに参加した学生が実習内容を報告し、その報告書及び発表内容を踏まえて単位を付与しており、毎年度20人程度の学生が単位を取得している。 ・情報学部では、地域協働の実践を経験しつつ、学生が自らのキャリアを考えるためのインターンシップを「インターンシップ実習Ⅰ、Ⅱ」科目として実施し、受講を推奨してきた。「インターンシップ実習Ⅰ、Ⅱ」では、インターンシップを希望する学生に対する受入先の紹介を、事務職員（キャリア支援係）、指導教員等が担当し、福知山市を中心に、毎年、官公庁（市役所、警察署）、民間企業（ソフトウェア開発、鉄道運輸、観光サービス、新聞社等）において20人程度の学生がインターンシップを行い、単位を取得している。単位取得にあたっては、Slackにおいてインターンシップ内容の報告及び質疑応答への参加を義務付けている。本科目は実際の業務を体験する貴重な機会であり、学生が進路を検討する上でも重要と考えられることから、令和８年度から開始する教育課程においても３年次の科目の一つとして設定した。 ・大学院地域情報学研究科では、大学院カリキュラムにインターンシップを科目として設定し、地域への大学院生のインターンシップへの参加を推し進めている。 【令和８年度・令和９年度の見込】 ・今後も学生の就職活動、とりわけインターンシップを取りまく環境は、さらなる早期化など大きな変化が予想される。常に最新のトレンドを注視し、充実したインターンシップ実現のため学生だけではなく企業にも呼びかけを継続する。 ・地域経営学部では、令和８年度カリキュラムにおいて、２・３年次開講のキャリア関連科目群として地域キャリア実習Ⅰ、Ⅱを設定しており、引き続き学生のインターンシップ支援を進めていく。 ・情報学部では、インターンシップを受け入れる企業は増えており、インターンシップに行く学生は増えていくことが予想される。このことから、令和８年度から実施する新しいカリキュラムにおいても、３年次開講のキャリア関連科目群としてインターンシップ実習Ⅰ、Ⅱを設定しており、引き続き学生のインターンシップ支援を進めていく。 ・大学院地域情報学研究科では、事務局のキャリア担当部局と連携し、地域企業の協力を得て、大学院生のインターンシップ先を継続的に確保する。 | E52: 4 | F52: ・インターンシップの実施方法等について、より学生がプログラムに興味を持つように、プログラム提供事業者向けのセミナーを開催するなど事業所にもアプローチし、学生と事業所間のマッチングを促進する。 ・京都府が運営する就職サイトとの連携を強化し、京都府内のインターンシップに参加しやすい体制に整備することで、府内のインターンシップ希望学生への案内を促進する。 | G52: ・初めての試みとして、４月にプログラム提供事業者向けに学生に選ばれるインターンシップ構築についてセミナーを実施し、事業所へのアプローチを行った。この研修には16社から参加があり、学生がインターンシップに求めている内容が知れたなど、非常に満足が約１割、満足が約６割の結果であった。 ・インターンシップの実績としては、実習先数は26事業所、参加学生は58人であった。１、２年次の学生の参加者が13人（前年度９人）に増加し、低学年次からキャリア観を醸成する機会として、本プログラムを提供できたと考える。 ・京都府と連携し、企業・学生双方に京都府が運営する就職サイトの案内を行い、サイトの利用を促進するとともに、インターンシップ情報の周知に努めた。特に学生向けには、学内イベントに参加した学生にチラシの配布や説明を実施した。 | H52: 3
B54: 13 | C54: ③教育における「福知山モデル」の提示
C55: ・地域と本学とが協働して持続可能な地域社会を創出する教育的試みを継続し、代表的実践例とその理論的背景を「福知山モデル」として取りまとめて提示する。 | D55: 【令和４年度～令和７年度の総括】 ・執行会議の下に「福知山モデル研究会」を設置し、令和４年度から令和６年度の間に計13回開催した。研究会では、第１期中期目標期間における取組みを振り返りながら、地域協働型教育、地域貢献、高大連携の在り方等について教職員で意見交換を行い、地域貢献を起点とする教育研究の基本的な方向性の整理を図った。令和６年度に開設した大学院地域情報学研究科においては、これらの議論を踏まえつつカリキュラム設計を進め、地域実践プロジェクトを重視した教育課程を構築した。 ・大学院地域情報学研究科の設置趣旨は、情報学を基盤として地域課題の解決に貢献する教育研究を進める点にあり、本学の地域協働型教育研究の新たな方向性を示すものとなった。こうした方向性を学部教育にも展開することで、教育研究を通じて地域社会に貢献する本学の独自性をより明確にするため、学長が示した組織改編案を基に、執行会議において学士課程教育の在り方について検討を重ねた。その結果、教育における「福知山モデル」と位置付ける「学士課程教育改編の方針」を令和６年３月に策定した。同方針では、「情報学を基盤とした地域協働型教育」及び「汎用的学修能力の育成」を新たな二つの教育目標として掲げるとともに、学部・学科の再編、共通教育を担う教員組織「基盤教育院」の設置、大学全体の三つのポリシーの策定等を示し、令和８年度以降の教育活動の基本的枠組みを明確化した。 ・令和６年度には学士課程教育刷新委員会を設置し、同委員会を中心に改編方針に基づく具体的な制度設計を進めた。全学及び各学部の三つのポリシーを策定し公表するとともに、令和８年度からの新たな教育課程の実施に向けた準備を整えた。併せて、執行会議における議論を通じて福知山モデルの具体化を進め、中間整理を行うなど、教育における「福知山モデル」の具現化を進めた。 【令和８年度・令和９年度の見込】 ・学士課程教育においては、令和８年度から適用する新しいカリキュラムを実施し、「学士課程教育改編の方針」を実質化する。「福知山モデル」については、中間報告案を基に内容の精緻化を進め、地域協働型教育の実践例と理論的背景との対応関係を整理した上で、第２期中期目標期間中に提示する。 | E55: 3 | F55: ・令和８年度からの学士課程教育改編案で示す「情報学を基盤とする地域協働型教育」及び「汎用的学修能力育成」の二つの教育目標を教育における「福知山モデル」に位置付ける。加えて、これまでの取組みを振り返り、「福知山モデル」に繋がる具体例を整理しながら、教育における「福知山モデル」の柱となりうる特徴を中間報告として取りまとめる。 | G55: ・「学士課程教育改編の方針」（令和６年３月策定）に基づく令和８年度カリキュラムの開講に向け、科目設計や実施方法等の具体的な内容について検討を進め、必要な準備を整えた。その中では、改編内容について全教職員の十分な理解を促進し、準備を円滑に進めることを目的として、学長文書「2026年度からの学士課程教育 ― これまでとは何が変わるのか」を作成し、学内で共有した。同文書では、従来の共通教育を再構築した基盤教育と専門教育の一体的かつ一貫的な運用、二つの教育目標の達成に向けた具体的な科目群の設置、従来の「ゼミ制度」を「指導教員制度」へ移行し、地域協働型教育の成果を学生の成長として結実させる仕組みの導入などを示し、教職員の理解を深めた。また、「福知山モデル」の構築に向け、その柱となりうる特徴をまとめた中間報告案を執行会議において協議し、同モデルの理論的フレームワークを中心に議論を深め、長期的な視点に立ったモデルの構築に向けて次年度に内容のさらなる精緻化を図ることを確認した。 | H55: 3
B56: 第４－１ 教育に関する目標
...

Sheet ⑤用語集（年計）
B2: 用語説明
B3: 小項目 番号 | C3: 用語 | D3: 用語解説
B4: 1 | C4: 三つのポリシー | D4: ディプロマ・ポリシー（学位授与方針）、カリキュラム・ポリシー（教育課程編成方針）、アドミッション・ポリシー（入学者受入れ方針）の３つのポリシーのこと。
B5: 1 | C5: ディプロマ・ポリシー（学位授与方針） | D5: 大学の教育理念を踏まえ、どのような力を身に付ければ学位を授与するのかを定める基本的な方針であり、学生の学修成果の目標ともなるもの。
B6: 1 | C6: カリキュラム・ポリシー（教育課程編成方針） | D6: ディプロマ・ポリシーの達成のために、どのような教育課程を編成し、どのような教育内容・方法を実施し、学修成果をどのように評価するのかを定める基本的な方針。
B7: 1 | C7: アドミッション・ポリシー（入学者受入れ方針） | D7: 大学・学部等の教育理念、ディプロマ・ポリシー、カリキュラム・ポリシーに基づく教育内容等を踏まえ、入学者を受け入れるための基本的な方針であり、受け入れる学生に求める学習成果（学力の三要素（１）知識・技能、（２）思考力・判断力、表現力等の能力、（３）主体性を持って多様な人々と協働して学ぶ態度）を示すもの。
B8: 8 | C8: 教育訓練給付金制度 | D8: 働く方々の主体的な能力開発やキャリア形成を支援し、雇用の安定と就職の促進を図ることを目的として、厚生労働大臣が指定する教育訓練を修了した際に、教育訓練経費の一部が支給される制度。 | E8: 追加
B9: 12 | C9: インターンシップ | D9: 学生が在学中に、企業等において自らの専攻や将来のキャリアに関連した就業体験を行うこと。
B10: 14 | C10: アセスメント・ポリシー（学修成果の評価方針） | D10: 学生の学修成果の評価（アセスメント）について、その目的、達成すべき質的水準及び具体的実施方法などについて定めた方針。
B11: 14 | C11: ＰＲＯＧテスト | D11: 専攻・専門に関わらず、社会で求められる汎用的な能力・態度・志向（ジェネリックスキル）について、リテラシーとコンピテンシーの２つの観点から測定する河合塾と㈱リアセックが共同開発したテスト。
B12: 14 | C12: ＧＰＡ | D12: 客観的な成績評価を行うため、授業科目ごとに０～４などのポイントを付した上で、学生ごとの成績の平均を算出すること。Grade Point Averageの略。本学では、成績評価を５段階（秀、優、良、可、不可）で評価し、それぞれに対してグレード・ポイント（４、３、２、１、０）を付与し、単位あたりの平均値を算出している。
B13: 15 | C13: シラバス | D13: 各授業科目の詳細な授業計画のこと。一般に、大学の授業名、担当教員名、講義目的、各回ごとの授業内容、成績評価方法・基準、準備学修等についての具体的な指示、教科書・参考文献、履修条件等が記されており、学生が各授業科目の準備学修等を進めるための基本となるもの。また、学生が講義の履修を決める際の資料になるとともに、教員相互の授業内容の調整、学生による授業評価等にも使われる。
B14: 16 | C14: ファカルティ・ディベロップメント（ＦＤ） | D14: 教員が授業内容・方法を改善し向上させるための組織的な取組の総称。具体的な例としては、教員相互の授業参観の実施、授業方法についての研究会の開催、新任教員のための研修会の開催等を挙げることができる。なお、大学設置基準等においては、こうした意味でのＦＤの実施を各大学に求めているが、単に授業内容・方法の改善のための研修に限らず、広く教育の改善、更には研究活動、社会貢献、管理運営に関わる教員団の職能開発の活動全般を指すものとしてＦＤの語を用いる場合もある。
B15: 20 | C15: リメディアル教育 | D15: 大学教育を受ける前提となる基礎的な知識等についての教育をいう。補習教育とも呼ばれる。
B16: 23 | C16: ピア・サポーター制度 | D16: 同じ立場の仲間（＝学生）同士が助け合い、支え合う学生による相互支援活動のこと。
B17: 34 | C17: 数理・データサイエンス・ＡＩ教育プログラム | D17: 学生の数理・データサイエンス・ＡＩへの関心を高め、それを適切に理解し活用する基礎的な能力（リテラシーレベル）や、課題を解決するための実践的な能力（応用基礎レベル）を育成するため、数理・データサイエンス・ＡＩに関する知識及び技術について体系的な教育を行う大学等の正規の課程（教育プログラム）を文部科学大臣が認定及び選定して奨励する制度。
B18: 35 | C18: Fab Lab（ファブラボ） | D18: ３Ｄプリンタやレーザーカッターなどデジタル制御された多様な工作機械を取り揃え、モノをつくる技術を地域住民が身につけることで、個人や地域レベルの課題を住民自身が解決できるようになるための市民参加型の次世代実験工房。
B19: 41 | C19: 科学研究費助成事業 | D19: 人文学、社会科学から自然科学まで全ての分野にわたり、基礎から応用までのあらゆる「学術研究」（研究者の自由な発想に基づく研究）を格段に発展させることを目的とする「競争的研究資金」であり、ピアレビューによる審査を経て、独創的・先駆的な研究に対する助成を行うもの。
B20: 41 | C20: ＵＲＡ（ユニバーシティー・リサーチ・アドミニストレーター） | D20: 大学などの研究組織において研究者および事務職員とともに、研究資源の導入促進、研究活動の企画・マネジメント、研究成果の活用促進を行って、研究者の研究活動の活性化や研究開発マネジメントの強化を支える業務に従事する人材のこと。 | E20: 追加
B21: 47 | C21: リカレント教育 | D21: 「学校教育」を、人々の生涯にわたって分散させようとする理念であり、その本来の意味は「職業上必要な知識・技術」を修得するために、フルタイムの就学とフルタイムの就職を繰り返すことである。一般的に「リカレント教育」を諸外国より広くとらえ、働きながら学ぶ場合、心の豊かさや生きがいのために学ぶ場合、学校以外の場で学ぶ場合もこれに含めている（この意味では成人の学習活動の全体に近い）。
B22: 48 | C22: デジタルファブリケーション技術 | D22: デジタルデータをもとに創造物を制作する技術のことである。３Ｄスキャナーや３Ｄ ＣＡＤなどの測定機械により、自分のアイデアや個人の身体データ等をデジタルデータ化した上で、そのようなデジタルデータを3Dプリンターやレーザーカッターなどのデジタル工作機械で読み込んで造形する。 | E22: 追加
B23: 51 | C23: Slack | D23: アメリカの企業が提供しているビジネス用のメッセージングアプリ。グループチャット、１対１のメッセージング（Direct Message）、音声通話をWebサービスとして提供している。
B24: 40 | C24: FUJIN(Fukuchiyama Universal Joint Information Nexus) | D24: 学内のＤＸ化を推進するために設置された「ＤＸ推進タスクフォース」が構築を進めている、学内データを集約し学内外に共有するためのデータ統合システム。
B25: 59 | C25: スタッフ・ディベロップメント（ＳＤ） | D25: 職員全員を対象とした、管理運営や教育・研究支援までを含めた資質向上のための組織的な取組を指す。なお、「職員」には教授等の教員や学長等の大学執行部、技術職員等も含まれる。
B26: 65 | C26: ERINGI | D26: 学内業務のＤＸ化の一環として、稟議決裁の電子化とペーパーレス化の推進を目的に、情報学部が開発した稟議決裁システム。
B27: 67 | C27: 認証評価制度 | D27: 学校教育法に基づき、全ての大学が７年以内に１回、文部科学大臣の認証を受けた評価機関（認証評価機関）による第三者評価（認証評価）を受けることが義務付けられる制度。国による事前規制を弾力化しつつ、大学等の教育研究の質の担保を図るため、設置後の大学等の組織運営や教育研究活動等の状況を定期的に事後確認する体制を整備する観点から導入された。
B28: 77 | C28: ＢＣＰ（事業継続計画） | D28: 自然災害、大火災、テロ攻撃などの緊急事態に遭遇した場合において、事業資産の損害を最小限にとどめつつ、中核となる事業の継続あるいは早期復旧を可能とするために、平常時に行うべき活動や緊急時における事業継続のための方法、手段などを取り決めておく計画のこと。
B29: 78 | C29: eduroam | D29: 初等・中等・高等教育機関や研究機関の間でキャンパス無線 LAN の相互利用を実現する、国際的なネットワークローミング利用の仕組み。

Sheet （参考）評価（年度）★
D1: ３．小項目別評価
D2: （１）2019年度の業務の実績に係る自己評価結果一覧表
D3: 大項目番号 | E3: 項目 | J3: 項目数 | K3: 自己評価 | U3: 平均点
K4: 5 | M4: 4 | O4: 3 | Q4: 2 | S4: 1
K6: 年度計画を大幅に上回って実施している（特に優れる若しくは顕著な成果がある） | M6: 年度計画を上回って実施している（上回る若しくは十分な実施状況） | O6: 年度計画を概ね実施している（実施） | Q6: 年度計画を十分に実施できていない（下回る若しくは実施が不十分） | S6: 年度計画を大幅に下回っている（特に劣る若しくは実施していない）
D7: 1 | E7: 第４ 教育研究等の質の向上に関する目標を達成するための措置 １ 教育の質の向上に関する目標を達成するための措置 | J7: =SUM(K7:T7) -> 31 | K7: =COUNTIF('(参考)第1期中期小項目別評価'!$I$14:$I$108,K$4) -> 1 | M7: =COUNTIF('(参考)第1期中期小項目別評価'!$I$14:$I$108,M$4) -> 12 | O7: =COUNTIF('(参考)第1期中期小項目別評価'!$I$14:$I$108,O$4) -> 18 | Q7: =COUNTIF('(参考)第1期中期小項目別評価'!$I$14:$I$108,Q$4) -> 0 | S7: =COUNTIF('(参考)第1期中期小項目別評価'!$I$14:$I$108,S$4) -> 0 | U7: =ROUND((K7*5+M7*4+O7*3+Q7*2+S7*1)/J7,1) -> 3.5
K8: =K7/$J$7 -> 0.032258065 | M8: =M7/$J$7 -> 0.38709677 | O8: =O7/$J$7 -> 0.58064516 | Q8: =Q7/$J$7 -> 0 | S8: =S7/$J$7 -> 0
D9: 2 | E9: 第４ 教育研究等の質の向上に関する目標を達成するための措置 ２ 研究の質の向上に関する目標を達成するための措置 | J9: =SUM(K9:T9) -> 10 | K9: =COUNTIF('(参考)第1期中期小項目別評価'!$I$123:$I$150,K$4) -> 0 | M9: =COUNTIF('(参考)第1期中期小項目別評価'!$I$123:$I$150,M$4) -> 3 | O9: =COUNTIF('(参考)第1期中期小項目別評価'!$I$123:$I$150,O$4) -> 6 | Q9: =COUNTIF('(参考)第1期中期小項目別評価'!$I$123:$I$150,Q$4) -> 1 | S9: =COUNTIF('(参考)第1期中期小項目別評価'!$I$123:$I$150,S$4) -> 0 | U9: =ROUND((K9*5+M9*4+O9*3+Q9*2+S9*1)/J9,1) -> 3.2
K10: =K9/$J$9 -> 0 | M10: =M9/$J$9 -> 0.3 | O10: =O9/$J$9 -> 0.6 | Q10: =Q9/$J$9 -> 0.1 | S10: =S9/$J$9 -> 0
D11: 3 | E11: 第４ 教育研究等の質の向上に関する目標を達成するための措置 ３ 地域協働（地域貢献）の質の向上に関する目標を達成するため の措置 | J11: =SUM(K11:T11) -> 10 | K11: =COUNTIF('(参考)第1期中期小項目別評価'!$I$164:$I$213,K$4) -> 0 | M11: =COUNTIF('(参考)第1期中期小項目別評価'!$I$164:$I$213,M$4) -> 2 | O11: =COUNTIF('(参考)第1期中期小項目別評価'!$I$164:$I$213,O$4) -> 8 | Q11: =COUNTIF('(参考)第1期中期小項目別評価'!$I$164:$I$213,Q$4) -> 0 | S11: =COUNTIF('(参考)第1期中期小項目別評価'!$I$164:$I$213,S$4) -> 0 | U11: =ROUND((K11*5+M11*4+O11*3+Q11*2+S11*1)/J11,1) -> 3.2
K12: =K11/$J$11 -> 0 | M12: =M11/$J$11 -> 0.2 | O12: =O11/$J$11 -> 0.8 | Q12: =Q11/$J$11 -> 0 | S12: =S11/$J$11 -> 0
D13: 4 | E13: 第５ 業務運営の改善及び効率化に関する目標を達成するための措置 | J13: =SUM(K13:T13) -> 20 | K13: =COUNTIF('(参考)第1期中期小項目別評価'!$I$222:$I$347,K$4) -> 0 | M13: =COUNTIF('(参考)第1期中期小項目別評価'!$I$222:$I$347,M$4) -> 5 | O13: =COUNTIF('(参考)第1期中期小項目別評価'!$I$222:$I$347,O$4) -> 15 | Q13: =COUNTIF('(参考)第1期中期小項目別評価'!$I$222:$I$347,Q$4) -> 0 | S13: =COUNTIF('(参考)第1期中期小項目別評価'!$I$222:$I$347,S$4) -> 0 | U13: =ROUND((K13*5+M13*4+O13*3+Q13*2+S13*1)/J13,1) -> 3.3
K14: =K13/$J$13 -> 0 | M14: =M13/$J$13 -> 0.25 | O14: =O13/$J$13 -> 0.75 | Q14: =Q13/$J$13 -> 0 | S14: =S13/$J$13 -> 0
D15: 5 | E15: 第６ 財務内容の改善に関する目標を達成するための措置 | J15: =SUM(K15:T15) -> 13 | K15: =COUNTIF('(参考)第1期中期小項目別評価'!$I$360:$I$443,K$4) -> 1 | M15: =COUNTIF('(参考)第1期中期小項目別評価'!$I$360:$I$443,M$4) -> 3 | O15: =COUNTIF('(参考)第1期中期小項目別評価'!$I$360:$I$443,O$4) -> 9 | Q15: =COUNTIF('(参考)第1期中期小項目別評価'!$I$360:$I$443,Q$4) -> 0 | S15: =COUNTIF('(参考)第1期中期小項目別評価'!$I$360:$I$443,S$4) -> 0 | U15: =ROUND((K15*5+M15*4+O15*3+Q15*2+S15*1)/J15,1) -> 3.4
K16: =K15/$J$15 -> 0.076923077 | M16: =M15/$J$15 -> 0.23076923 | O16: =O15/$J$15 -> 0.69230769 | Q16: =Q15/$J$15 -> 0 | S16: =S15/$J$15 -> 0
D17: 6 | E17: 第７ 自己点検・評価及び情報公開に関する目標を達成するための措置 | J17: =SUM(K17:T17) -> 11 | K17: =COUNTIF('(参考)第1期中期小項目別評価'!$I$456:$I$505,K$4) -> 0 | M17: =COUNTIF('(参考)第1期中期小項目別評価'!$I$456:$I$505,M$4) -> 3 | O17: =COUNTIF('(参考)第1期中期小項目別評価'!$I$456:$I$505,O$4) -> 8 | Q17: =COUNTIF('(参考)第1期中期小項目別評価'!$I$456:$I$505,Q$4) -> 0 | S17: =COUNTIF('(参考)第1期中期小項目別評価'!$I$456:$I$505,S$4) -> 0 | U17: =ROUND((K17*5+M17*4+O17*3+Q17*2+S17*1)/J17,1) -> 3.3
K18: =K17/$J$17 -> 0 | M18: =M17/$J$17 -> 0.27272727 | O18: =O17/$J$17 -> 0.72727273 | Q18: =Q17/$J$17 -> 0 | S18: =S17/$J$17 -> 0
D19: 7 | E19: 第８ その他業務運営に関する重要目標を達成するための措置 | J19: =SUM(K19:T19) -> 7 | K19: =COUNTIF('(参考)第1期中期小項目別評価'!$I$517:$I$555,K$4) -> 0 | M19: =COUNTIF('(参考)第1期中期小項目別評価'!$I$517:$I$555,M$4) -> 1 | O19: =COUNTIF('(参考)第1期中期小項目別評価'!$I$517:$I$555,O$4) -> 6 | Q19: =COUNTIF('(参考)第1期中期小項目別評価'!$I$517:$I$555,Q$4) -> 0 | S19: =COUNTIF('(参考)第1期中期小項目別評価'!$I$517:$I$555,S$4) -> 0 | U19: =ROUND((K19*5+M19*4+O19*3+Q19*2+S19*1)/J19,1) -> 3.1
K20: =K19/$J$19 -> 0 | M20: =M19/$J$19 -> 0.14285714 | O20: =O19/$J$19 -> 0.85714286 | Q20: =Q19/$J$19 -> 0 | S20: =S19/$J$19 -> 0
D21: 8 | E21: 第14 福知山市の規則で定める業務運営に関する事項 | J21: =SUM(K21:T21) -> 4 | K21: =COUNTIF('(参考)第1期中期小項目別評価'!$I$596:$I$603,K$4) -> 0 | M21: =COUNTIF('(参考)第1期中期小項目別評価'!$I$596:$I$603,M$4) -> 1 | O21: =COUNTIF('(参考)第1期中期小項目別評価'!$I$596:$I$603,O$4) -> 3 | Q21: =COUNTIF('(参考)第1期中期小項目別評価'!$I$596:$I$603,Q$4) -> 0 | S21: =COUNTIF('(参考)第1期中期小項目別評価'!$I$596:$I$603,S$4) -> 0 | U21: =ROUND((K21*5+M21*4+O21*3+Q21*2+S21*1)/J21,1) -> 3.3
K22: =K21/$J21 -> 0 | M22: =M21/$J$21 -> 0.25 | O22: =O21/$J$21 -> 0.75 | Q22: =Q21/$J$21 -> 0 | S22: =S21/$J$21 -> 0
E23: 合計 | J23: =SUM(J7:J22) -> 106 | K23: =K7+K9+K11+K13+K15+K17+K19+K21 -> 2 | M23: =M7+M9+M11+M13+M15+M17+M19+M21 -> 30 | O23: =O7+O9+O11+O13+O15+O17+O19+O21 -> 73 | Q23: =Q7+Q9+Q11+Q13+Q15+Q17+Q19+Q21 -> 1 | S23: =S7+S9+S11+S13+S15+S17+S19+S21 -> 0 | U23: =ROUND((K23*5+M23*4+O23*3+Q23*2+S23*1)/J23,1) -> 3.3
K24: =K23/$J$23 -> 0.018867925 | M24: =M23/$J$23 -> 0.28301887 | O24: =O23/$J$23 -> 0.68867925 | Q24: =Q23/$J$23 -> 0.0094339623 | S24: =S23/$J$23 -> 0

Sheet （参考）評価（中期）★
D2: （２）中期目標期間（4年終了時）の業務の実績に係る自己評価結果一覧表
D3: 大項目番号 | E3: 項目 | J3: 項目数 | K3: 自己評価 | U3: 平均点
K4: 5 | M4: 4 | O4: 3 | Q4: 2 | S4: 1
K6: 中期計画を大幅に上回って実施している（特に優れる若しくは顕著な成果がある） | M6: 中期計画を上回って実施している（上回る若しくは十分な実施状況） | O6: 中期計画を概ね実施している（実施） | Q6: 中期計画を十分に実施できていない（下回る若しくは実施が不十分） | S6: 中期計画を大幅に下回っている（特に劣る若しくは実施していない）
D7: 1 | E7: 第４ 教育研究等の質の向上に関する目標を達成するための措置 １ 教育の質の向上に関する目標を達成するための措置 | J7: =SUM(K7:T7) -> 16 | K7: =COUNTIF('(参考)第1期中期小項目別評価'!$E$14:$E$108,K$4) -> 1 | M7: =COUNTIF('(参考)第1期中期小項目別評価'!$E$14:$E$108,M$4) -> 8 | O7: =COUNTIF('(参考)第1期中期小項目別評価'!$E$14:$E$108,O$4) -> 7 | Q7: =COUNTIF('(参考)第1期中期小項目別評価'!$E$14:$E$108,Q$4) -> 0 | S7: =COUNTIF('(参考)第1期中期小項目別評価'!$E$14:$E$108,S$4) -> 0 | U7: =ROUND((K7*5+M7*4+O7*3+Q7*2+S7*1)/J7,1) -> 3.6
K8: =K7/$J$7 -> 0.0625 | M8: =M7/$J$7 -> 0.5 | O8: =O7/$J$7 -> 0.4375 | Q8: =Q7/$J$7 -> 0 | S8: =S7/$J$7 -> 0
D9: 2 | E9: 第４ 教育研究等の質の向上に関する目標を達成するための措置 ２ 研究の質の向上に関する目標を達成するための措置 | J9: =SUM(K9:T9) -> 7 | K9: =COUNTIF('(参考)第1期中期小項目別評価'!$E$123:$E$150,K$4) -> 0 | M9: =COUNTIF('(参考)第1期中期小項目別評価'!$E$123:$E$150,M$4) -> 1 | O9: =COUNTIF('(参考)第1期中期小項目別評価'!$E$123:$E$150,O$4) -> 6 | Q9: =COUNTIF('(参考)第1期中期小項目別評価'!$E$123:$E$150,Q$4) -> 0 | S9: =COUNTIF('(参考)第1期中期小項目別評価'!$E$123:$E$150,S$4) -> 0 | U9: =ROUND((K9*5+M9*4+O9*3+Q9*2+S9*1)/J9,1) -> 3.1
K10: =K9/$J$9 -> 0 | M10: =M9/$J$9 -> 0.14285714 | O10: =O9/$J$9 -> 0.85714286 | Q10: =Q9/$J$9 -> 0 | S10: =S9/$J$9 -> 0
D11: 3 | E11: 第４ 教育研究等の質の向上に関する目標を達成するための措置 ３ 地域協働（地域貢献）の質の向上に関する目標を達成するため の措置 | J11: =SUM(K11:T11) -> 8 | K11: =COUNTIF('(参考)第1期中期小項目別評価'!$E$164:$E$213,K$4) -> 0 | M11: =COUNTIF('(参考)第1期中期小項目別評価'!$E$164:$E$213,M$4) -> 5 | O11: =COUNTIF('(参考)第1期中期小項目別評価'!$E$164:$E$213,O$4) -> 3 | Q11: =COUNTIF('(参考)第1期中期小項目別評価'!$E$164:$E$213,Q$4) -> 0 | S11: =COUNTIF('(参考)第1期中期小項目別評価'!$E$164:$E$213,S$4) -> 0 | U11: =ROUND((K11*5+M11*4+O11*3+Q11*2+S11*1)/J11,1) -> 3.6
K12: =K11/$J$11 -> 0 | M12: =M11/$J$11 -> 0.625 | O12: =O11/$J$11 -> 0.375 | Q12: =Q11/$J$11 -> 0 | S12: =S11/$J$11 -> 0
D13: 4 | E13: 第５ 業務運営の改善及び効率化に関する目標を達成するための措置 | J13: =SUM(K13:T13) -> 19 | K13: =COUNTIF('(参考)第1期中期小項目別評価'!$E$222:$E$347,K$4) -> 0 | M13: =COUNTIF('(参考)第1期中期小項目別評価'!$E$222:$E$347,M$4) -> 3 | O13: =COUNTIF('(参考)第1期中期小項目別評価'!$E$222:$E$347,O$4) -> 16 | Q13: =COUNTIF('(参考)第1期中期小項目別評価'!$E$222:$E$347,Q$4) -> 0 | S13: =COUNTIF('(参考)第1期中期小項目別評価'!$E$222:$E$347,S$4) -> 0 | U13: =ROUND((K13*5+M13*4+O13*3+Q13*2+S13*1)/J13,1) -> 3.2
K14: =K13/$J$13 -> 0 | M14: =M13/$J$13 -> 0.15789474 | O14: =O13/$J$13 -> 0.84210526 | Q14: =Q13/$J$13 -> 0 | S14: =S13/$J$13 -> 0
D15: 5 | E15: 第６ 財務内容の改善に関する目標を達成するための措置 | J15: =SUM(K15:T15) -> 12 | K15: =COUNTIF('(参考)第1期中期小項目別評価'!$E$360:$E$443,K$4) -> 1 | M15: =COUNTIF('(参考)第1期中期小項目別評価'!$E$360:$E$443,M$4) -> 2 | O15: =COUNTIF('(参考)第1期中期小項目別評価'!$E$360:$E$443,O$4) -> 9 | Q15: =COUNTIF('(参考)第1期中期小項目別評価'!$E$360:$E$443,Q$4) -> 0 | S15: =COUNTIF('(参考)第1期中期小項目別評価'!$E$360:$E$443,S$4) -> 0 | U15: =ROUND((K15*5+M15*4+O15*3+Q15*2+S15*1)/J15,1) -> 3.3
K16: =K15/$J$15 -> 0.083333333 | M16: =M15/$J$15 -> 0.16666667 | O16: =O15/$J$15 -> 0.75 | Q16: =Q15/$J$15 -> 0 | S16: =S15/$J$15 -> 0
D17: 6 | E17: 第７ 自己点検・評価及び情報公開に関する目標を達成するための措置 | J17: =SUM(K17:T17) -> 10 | K17: =COUNTIF('(参考)第1期中期小項目別評価'!$E$456:$E$503,K$4) -> 1 | M17: =COUNTIF('(参考)第1期中期小項目別評価'!$E$456:$E$503,M$4) -> 2 | O17: =COUNTIF('(参考)第1期中期小項目別評価'!$E$456:$E$503,O$4) -> 7 | Q17: =COUNTIF('(参考)第1期中期小項目別評価'!$E$456:$E$503,Q$4) -> 0 | S17: =COUNTIF('(参考)第1期中期小項目別評価'!$E$456:$E$503,S$4) -> 0 | U17: =ROUND((K17*5+M17*4+O17*3+Q17*2+S17*1)/J17,1) -> 3.4
K18: =K17/$J$17 -> 0.1 | M18: =M17/$J$17 -> 0.2 | O18: =O17/$J$17 -> 0.7 | Q18: =Q17/$J$17 -> 0 | S18: =S17/$J$17 -> 0
D19: 7 | E19: 第８ その他業務運営に関する重要目標を達成するための措置 | J19: =SUM(K19:T19) -> 6 | K19: =COUNTIF('(参考)第1期中期小項目別評価'!$E$517:$E$555,K$4) -> 0 | M19: =COUNTIF('(参考)第1期中期小項目別評価'!$E$517:$E$555,M$4) -> 1 | O19: =COUNTIF('(参考)第1期中期小項目別評価'!$E$517:$E$555,O$4) -> 5 | Q19: =COUNTIF('(参考)第1期中期小項目別評価'!$E$517:$E$555,Q$4) -> 0 | S19: =COUNTIF('(参考)第1期中期小項目別評価'!$E$517:$E$555,S$4) -> 0 | U19: =ROUND((K19*5+M19*4+O19*3+Q19*2+S19*1)/J19,1) -> 3.2
K20: =K19/$J$19 -> 0 | M20: =M19/$J$19 -> 0.16666667 | O20: =O19/$J$19 -> 0.83333333 | Q20: =Q19/$J$19 -> 0 | S20: =S19/$J$19 -> 0
D21: 8 | E21: 第14 福知山市の規則で定める業務運営に関する事項 | J21: =SUM(K21:T21) -> 4 | K21: =COUNTIF('(参考)第1期中期小項目別評価'!$E$596:$E$603,K$4) -> 0 | M21: =COUNTIF('(参考)第1期中期小項目別評価'!$E$596:$E$603,M$4) -> 1 | O21: =COUNTIF('(参考)第1期中期小項目別評価'!$E$596:$E$603,O$4) -> 3 | Q21: =COUNTIF('(参考)第1期中期小項目別評価'!$E$596:$E$603,Q$4) -> 0 | S21: =COUNTIF('(参考)第1期中期小項目別評価'!$E$596:$E$603,S$4) -> 0 | U21: =ROUND((K21*5+M21*4+O21*3+Q21*2+S21*1)/J21,1) -> 3.3
K22: =K21/$J21 -> 0 | M22: =M21/$J21 -> 0.25 | O22: =O21/$J21 -> 0.75 | Q22: =Q21/$J21 -> 0 | S22: =S21/$J21 -> 0
E23: 合計 | J23: =SUM(J7:J22) -> 82 | K23: =K7+K9+K11+K13+K15+K17+K19+K21 -> 3 | M23: =M7+M9+M11+M13+M15+M17+M19+M21 -> 23 | O23: =O7+O9+O11+O13+O15+O17+O19+O21 -> 56 | Q23: =Q7+Q9+Q11+Q13+Q15+Q17+Q19+Q21 -> 0 | S23: =S7+S9+S11+S13+S15+S17+S19+S21 -> 0 | U23: =ROUND((K23*5+M23*4+O23*3+Q23*2+S23*1)/J23,1) -> 3.4
K24: =K23/$J$23 -> 0.036585366 | M24: =M23/$J$23 -> 0.2804878 | O24: =O23/$J$23 -> 0.68292683 | Q24: =Q23/$J$23 -> 0 | S24: =S23/$J$23 -> 0

Sheet (参考)第1期中期小項目別評価
B1: （３）小項目別業務実績・自己評価結果
B2: 項 目 別 の 状 況
B4: 第４ 教育研究等の質の向上に関する目標
B5: １ 教育の質の向上に関する目標 （１）教育の成果に関する目標
B7: 中 期 目 標 | D7: 教育研究において、地域、自国、そして世界に対する理想を持ち、教養・専門的知識を生涯にわたって学修し、それを実践する力を涵養する。 特に、地域協働型教育研究を通して、創造的思考力、課題解決力、協働・協調力、コミュニケーション力など、社会人に必要となる基礎能力を涵養する。地域社会そのものを教育の場としたフィールドワークやインターンシップに主体的に取り組み、地域の人や資源を教材とした教育研究を実践する中で、地域社会が抱える様々な課題解決に向け、関係者や関係機関等との協議調整、企画立案や提案を行うことができる人材を育て、地域社会に還元する。
B9: 中期計画番号 | C9: 中期計画 | D9: 業務の実績（中期計画） | E9: 自己 評価 | F9: 年度計画番号 | G9: 年度計画 | H9: 業務の実績（年度計画） | I9: 自己 評価
B11: １ 教育研究等の質の向上に関する目標を達成するための措置
B12: （１）教育の成果に関する目標を達成するための取組
B13: 1 | C13: ①自由な発想と行動力、分析企画力、実行力、公共マインドの涵養
C14: 大学の理念の実現と発展に必要な長期的な戦略を計画し、地域に根ざし、世界に通用する高い専門能力と多角的な視点を持ち、さらに、地域社会の様々な分野におけるニーズに対応した指導的役割を果たせる人材を育成するための自由な発想と行動力、分析企画力、実行力、公共マインドを涵養する。 | D14: 【2016年度～2019年度の総括】 ・大学の理念を実現するため、2017年度に地域経営学部のカリキュラムを改定し、地域と協働でフィールドワーク等を行う演習科目を必修化するとともに、幅広い知識、多角的な視点を養うために教養科目の充実を図った。2020年度の情報学部設置に向けて、カリキュラムを作成するとともに既存学部のカリキュラムの体系化を進めるため、ナンバリング、履修モデル、カリキュラムツリーの作成を行い、また、シラバスの充実を図り、地域人財（グローカリスト）の育成における方向性の確立に努めた。 【2020年度・2021年度の見込】 ・2017年度に策定したカリキュラムの卒業生を2020年度に輩出するため、本カリキュラムの検証を行う。また、教養科目や地域協働型教育研究など、地域経営学部と情報学部の教育・研究上の具体的な連携の方法について検討する。 | E14: 4 | F14: 1 | G14: ・新学部の設置に伴い、既存学部のカリキュラムを見直し、ディプロマポリシーの実現を意識しつつ、2020年度新カリキュラムを策定する（編成実施方針、科目配置表等）。 新学部の開設に合わせた教学体制の整備の一環として、カリキュラムにナンバリングを付し、新学部も含めて大学全体で教育課程の体系性を確保する。ナンバリングの体系化は2019年末に完成させ、2020年度には学生に公開し、完全施行する。ナンバリングを付すことにより、学生にとっては、体系的、計画的に履修することができ、教員は体系的で効果的な履修指導を行うことができる。 | H14: ・情報学部の設置に伴い、両学部間で調整の上、共通教育科目の見直しを行った。また、専門科目についても見直しを行い、新設する情報学部に対応した2020年度カリキュラムを作成した。 ・共通教育科目及び地域経営学部と情報学部の専門教育科目に科目ナンバリングを付し、大学全体の教育課程の体系を確保した。これに加え、体系的かつ計画的な履修を促すため地域経営学部は履修モデルの見直しやシラバスの充実（シラバス項目の見直し、教務委員会によるシラバスチェック）、演習科目のルーブリックや修学カルテの試行的導入などを行った。また、学部学科ごとのカリキュラムツリーも作成した。 | I14: 4
F15: 2 | G15: ・一部の授業では、学外講師を招聘することにより、自由な発想と行動力、分析企画力、実行力、公共マインドを養成する。その適切性は、学生の授業評価アンケートなどから検証する。学外講師にも本学の３ポリシーを意識頂くよう努める。教務委員会で学外講師のカリキュラム上の必要性と位置づけを明確にする。また、FD委員会とも協力し専任教員への大学の理念の浸透を図る。 | H15: ・学外講師を招聘した結果、学生の授業評価アンケートで、「ゲストスピーカーの話を聞くことで学んだことの理解が深まった」「様々な視点や考え方を知ることができた」などの声があり、様々な業種の現場の生の声を取り入れることで深い学びに繋がり、自由な発想と行動力、分析企画力、実行力、公共マインドを養成した。 ・学外講師にも本学の理念や3ポリシーを周知するため、選考時の説明や毎年度の始めの履修の手引きの配布など、本学の理念の共有を図った。 ・専任教員には､入職時のガイダンスの説明や履修の手引きの配付等により周知している。 | I15: 3
B16: 2 | C16: ②行動・実践の基盤である生きていくための総合力(人間力)を涵養する教養教育の重視
C17: 幅広い視野と豊かな人間性を涵養し、創造的思考力、課題解決力、協調・協働力、コミュニケーション力といった社会人基礎力など、行動･実践の基盤である生きていくための総合力(人間力)を涵養するためにインターンシップ等も取り入れた教養教育を実践する。 | D17: 【2016年度～2019年度の総括】 ・社会とのつながりの中で学びを深め、社会人基礎力を養うため、2017年度及び2020年度の二度にわたるカリキュラムの改定により、本学ではインターンシップ（グローカル特別講義（地域キャリア実習））や国際フィールドワーク、病院実習といった実習科目を積極的に取り入れた授業を実施してきた。これにより、課題解決力、協調・協働力、コミュニケーション力などを涵養している。 【2020年度・2021年度の見込】 ・地域経営学部では、これまでと同様にインターンシップ（地域キャリア実習）や国際フィールドワーク、病院実習といった実習科目の履修を積極的に促す。情報学部ではPBL（課題解決型学習）を実施するとともに、3年次生に配当されているインターンシップの実施に向けて、実習先を確保する。 | E17: 3 | F17: 3 | G17: ・授業科目である「国際フィールドワーク」においては、海外における地域事情を知ることを目的とし、中国でのフィールドワークを行う。現地学生との交流を行い、世界的視野で考え、足元から行動する能力やコミュニケーション力を養う。 | H17: ・授業科目「国際フィールドワーク」において、9月2日から7日に3人の学生が中国研修を行った。中国の農村地域を訪問し、中国型地域づくりの手法を学び、農村社会の発展の現状を把握できた。現地の若者達と地域づくりの課題解決を巡って日中両国の知見を交換した。国際フィールドワークの全体を通して、学生達は広い視野を身につけ、自ら行動する能力やコミュニケーション能力を養った。 | I17: 3
F18: 4 | G18: ・課題解決型の実習を｢地域キャリア実習｣という科目名で、2019年度も引き続き実施する。座学で学んだことを現場で実践する機会を与えることで学士力、社会人基礎力の養成に努める。 | H18: ・学士力・社会人基礎力を養成するため、インターンシップ協力先の開拓を強化し、北近畿地域の事業所を中心に52事業所からプログラムの提供を受けた。その結果、22事業所に延べ61人の学生がグローカル特別講義Ⅲ（地域キャリア実習Ⅰ）に参加した。学生にとって、「地域で働くこと」｢仕事観･人生観を醸成｣ ｢残りの学生生活ですべきことを明確にする｣という点で貴重な機会となった。実習後は、実習参加者全員が報告書（A4・2枚）や実習日誌の提出、ポスター報告を実施し、10日以上の実習参加者14人（23％）に対して単位認定をした。 ・11月28日には実習の内容と成果をまとめて、ポスターセッション形式の報告会を実施した。 | I18: 3
B19: 3 | C19: ③理論と応用の学びを踏まえた実践・実習による学びの徹底
C20: 様々な地域課題に対し、質の高い理論による専門教育と地域協働型の実践教育を通じ課題解決能力を養成し、協議調整や企画立案を行うことができる人材を育て、地域社会に還元する。 | D20: 【2016年度～2019年度の総括】 ・地域協働型教育の実践を行い、地域の課題と直接向き合うフィールドワークを福知山市をはじめとした北近畿地域で展開してきた。2016年度から地域協働型実践教育成果報告会を毎年2月に開催し、連携先による講評の機会を設けている。また、現地報告会を実施するなど、プレゼンテーション能力や課題解決能力の向上に努めた。 ・地域協働型の教育での学びは、修学カルテによる自己評価に加え、演習科目ではルーブリックを活用し、演習における知識・技能・遂行能力の習熟度の評価を明確化した。 【2020年度・2021年度の見込】 ・情報学部を設置したことで、幅広い分野で地域連携を行うことが期待されていることから、連携先の開拓を随時行う。地域経営学部においては、引き続き積極的に地域との接点を持ち、地域課題と向き合う教育を実践していく。 | E20: 4 | F20: 5 | G20: ・理論と応用の学びを踏まえた実践・実習による学びを強化し、学修アウトカムの達成度を見るためにルーブリックを作成する。ルーブリックは、学生の課題を確認し、その成長に資するものであり、webシステムの導入とも合わせて、1年生科目「地域経営演習Ⅰ、Ⅱ」で試行的に導入する。 | H20: ・理論と応用の学びを踏まえた実践・実習による学びを強化し、学修アウトカムの達成度を見るためにルーブリックを作成した。1年次生科目「地域経営演習」の成績評価にあたって、「知識」「技能」「遂行能力」について、作成したルーブリックを用いてその習熟度を測ることにより、従来のクラスによる評価のばらつきを一定程度抑制する効果があった。1年次生科目「地域経営演習Ⅰ・Ⅱ」で試行的に実施し、さらに効果の検証を行った。 | I20: 4
B21: 4 | C21: ④主体的な学びの支援・推進
C22: 学生のリーダーシップやモチベーションを向上させる取り組みを進めるとともに、ワークショップ等のグループ学修を含め、共感性を養いながら学生自らが主体的に学修を進めるアクティブ・ラーニングを推進する。 | D22: 【2016年度～2019年度の総括】 ・地域で活躍するキーパーソンを一部の授業のゲスト講師として招いたほか、行政職員の現場の声を聞く機会を設け、授業内容を深めるだけでなく学生のモチベーション向上に取り組んだ。 ・授業に適宜グループワークやグループディスカッションを取り入れることで、学生の主体性やコミュニケーション能力を養った。 ・教育効果を検証するため、2019年度後学期から学生の自己評価により学修の習熟度（プロジェクトの実施経験やリーダーシップ、他者とのコミュニケーション等）を修学カルテに蓄積している。 【2020年度・2021年度の見込】 ・学生が学びを深めるために、引き続き、適切な形でゲスト講師の招聘やグループワーク、グループディスカッションを授業に取り入れていく。 | E22: 4 | F22: 6 | G22: ・学生プロジェクトへの単位付与を実施する。2020年度より本格実施に向けて見直しを行う。単位認定の基準としては2単位に相当する時間数を確保することとした。（科目はグローカル特別講義である） | H22: ・2019年度前学期に10件の学生プロジェクトを採択した。そのうち、学生プロジェクト「キャリアパス0.1」について単位を認定した（1件・7人）。 | I22: 3
F23: 7 | G23: ・ポートフォリオは、導入する学務システムの機能を用いて、2019年度前期中に詳細を決定するとともに、2年生から試行的に導入する。 | H23: ・教育効果の検証とプロジェクトの実施経験やリーダーシップなど学生自身の学修の習熟度や大学生活での学びや経験を記録するためのツールとして「修学カルテ」という名称で本学におけるポートフォリオを作成した。ポートフォリオは、教学情報システム「WebClass」の修学カルテ機能を用いて試案を作成し、後学期のオリエンテーションにおいて、2年次生を対象に試行的に実施し、学びを振り返る機会を設けた。 ・試行実施の結果を踏まえて内容を修正し、新年度に向けたオリエンテーションにて、新2年次生から4年次生を対象にポートフォリオを実施する。 | I23: 4
B25: 第４ 教育研究等の質の向上に関する目標
B26: １ 教育の質の向上に関する目標 （２）教育の内容等に関する目標 ①学位授与に関する目標
B28: 中 期 目 標 | D28: 基本理念・目的を踏まえ、どのような人材を育成し、どのような力を身に付けた者に学位を授与するのかを定める基本方針として、ディプロマ・ポリシー（学位授与の方針）を明確化し、学生の学修成果目標を明示する。
B30: 中期計画番号 | C30: 中期計画 | D30: 業務の実績（中期計画） | E30: 自己 評価 | F30: 年度計画 番号 | G30: 年度計画 | H30: 業務の実績（年度計画） | I30: 自己 評価
B32: １ 教育研究等の質の向上に関する目標を達成するための措置
B33: （２）教育の内容等に関する目標を達成するための措置
B34: 5 | C34: ①学位授与の明確化
C35: 本学が育成する人材像に基づき、ディプロマ・ポリシーを明確に定め、教育の成果に関する目標に基づく教育と評価により、学生及び社会に対して教育の質を保証する。 | D35: 【2016年度～2019年度の総括】 ・本学の理念に基づくディプロマ・ポリシー（学位授与方針）を明確にし、学生の学位授与に係る学修アウトカム目標を設定した。未確立の「地域経営学」の定義等の研究を深め、ディプロマ・ポリシーを2016年度及び2019年度に見直しを行い、2017年度及び2020年度に改定した。 ・学位授与方針と科目との関連性をカリキュラムマップとしてまとめ、それぞれのシラバスにも明記し、科目の位置づけを明確化した。 ・成績評価にあたってはGPA評価制度を採用しており、履修指導時に活用するとともに、成績優秀者には履修登録上限単位数を広げる等の活用をしている。 【2020年度・2021年度の見込】 ・ディプロマ・ポリシーに基づき、卒業までに学生が学ぶべき内容を保証するために、2020年度カリキュラムに基づいた授業の実施を行うとともに、成績評価の厳格化についての検討を進めていく。 | E35: 3 | F35: 8 | G35: ・授業評価アンケート結果に基づき、シラバス通りに授業が展開されているか検証するとともに、実態把握のために教員間の授業参観を実施する。 ・シラバスの作成においては、以下の記入を徹底する。 予習、復習の内容と注意事項 試験・レポート等に対するフィードバックの方法 到達目標、成績評価の方法、基準 卒業認定、学位授与方法との関係 ・成績評価の分布状況について、2019年度より教員間で公表する。教員間・科目間で偏りがないよう、成績評価の割合などについて検討する。 | H35: ・授業評価アンケートでは、授業がシラバス通りに展開されているかという項目に対して、評価の全体平均が前学期4.08で後学期4.01となり、概ね良い評価となった。 ・後学期の授業中において授業参観を実施し、教員相互に授業を観ることによって自身の授業改善に努めるようにした。 ・2020年度シラバス作成要領を見直し、成績評価と到達目標の関連性を組織的にチェックする体制を取るとともに、シラバスの内容充実を図った。 ・2018年度に作成した評価基準を基にした成績評価の分布状況を2019年度より教員間で公表し共有することで、担当科目以外の成績評価状況を把握することができる体制とした。 | I35: 4
B37: 第４ 教育研究等の質の向上に関する目標
B38: １ 教育の質の向上に関する目標 （２）教育の内容等に関する目標 ②教育内容・手法の充実に関する目標
B40: 中 期 目 標 | D40: ディプロマ・ポリシーの達成のために、どのような教育課程を編成し、どのような教育内容・方法を実施し、学修成果をどのように評価するのかを定める基本的な方針として、カリキュラム・ポリシー（教育課程編成・実施の方針）を明確化する。 また、社会や学生のニーズに照らして、教育内容とその手法について常に最適化を図るため、カリキュラム（教育課程）の見直しとファカルティ・ディベロップメント授業方法・内容を改善・向上させるための組織的な取り組みの総称をいう。）を推進する。
B42: 中期計画番号 | C42: 中期計画 | D42: 業務の実績（中期計画） | E42: 自己 評価 | F42: 年度計画 番号 | G42: 年度計画 | H42: 業務の実績（年度計画） | I42: 自己 評価
B44: １ 教育研究等の質の向上に関する目標を達成するための措置
B45: （２）教育の内容等に関する目標を達成するための措置
B46: ②教育内容･手法の充実
B47: 6 | C47: ア カリキュラムの充実等
C48: ディプロマ・ポリシーを踏まえた明確なカリキュラム・ポリシーを策定する。併せて、各授業の到達目標、授業計画、成績評価の方法と基準等を明示したシラバスの充実化を図る。 | D48: 【2016年度～2019年度の総括】 ・ディプロマ・ポリシー（学位授与方針）を踏まえた明確なカリキュラム・ポリシーを2017年度に改定し、これに基づくカリキュラムを2017年度から改定した。未確立の「地域経営学」の定義等の研究を深め、ディプロマ・ポリシーを2016年度および2019年度に見直し作業を行い、2017年度及び2020年度に改定した。 ・カリキュラムに配当された科目の講義概要（シラバス）の作成にあたっては、授業内容や到達目標、評価基準などをチェックし、その質を保証している。 ・年2回実施している授業評価アンケートにおいて、シラバスと授業内容の整合性を確認するために、2017年度から「シラバスどおりに授業が展開されているか」の項目を追加した。 ・2018年度よりカリキュラムの検証・見直しを行い、2020年度カリキュラムを策定するとともに、シラバスの内容を充実させた。 【2020年度・2021年度の見込】 ・講義概要（シラバス）作成時のチェックと授業評価アンケートにより、授業内容の質を保証していく。 | E48: 3 | F48: 9 | G48: ・シラバスの入力及び閲覧についてシステムの導入によりオンライン上で可能とし、シラバスの作成をより迅速に行い確認ができるようにする。シラバスに当該科目とディプロマポリシーの関係を明示し、併せてシラバスの点検を行う。 | H48: ・シラバスの作成にあたってはオンライン上で可能とし、その作成を迅速に行うとともに、シラバス作成チェックリストに基づき教務委員会により組織的に点検を行うことができた。シラバスに当該科目とディプロマ・ポリシーの関係を明示した。併せてシラバスの点検結果をフィードバックすることで改善が見られた。 | I48: 3
B49: 7 | C49: イ ファカルティ・ディベロップメント（FD）の推進
C50: 教育に関する自己点検･評価を行うとともに、外部評価を定期的に受審する。また、組織的なファカルティ・ディベロップメント（FD）に関する研修、他大学教員との交流等を実施し、その成果を教育内容や教育手法の改善に活用する。併せて、学生の授業評価を定期的に実施し、教育活動の改善に反映する。 | D50: 【2016年度～2019年度の総括】 ・開学より、教員研修や教員同士の交流の機会を設けるために月1回程度のFDフォーラムを実施した。授業改善や情報セキュリティ、地域経営学、教学情報システム「WebClass」の活用方法など、外部講師も招聘しながら研修を行った。 ・2016年度より無記名の授業アンケートを実施し、講義担当教員にその集計結果を返却してリフレクションペーパー（振り返りシート）を記入することで、学生の理解度や講義の改善点を自覚させるよう工夫した。集計は2018年度より教学情報システムを導入し、スマートフォンを活用したWebアンケートを実施するなど、事務負担を削減するとともに集計の迅速化を図った。 ・2019年度には、全教員が他の教員の授業参観を実施し、参観者との意見交換を行い相互の指導技術の改善に取り組んだ。 【2020年度・2021年度の見込】 ・情報学部に導入するPBLや帰納的学習などの新しい教育手法について、評価の方法を検討する。 ・学生も含めた学部間の交流を図り、教育技能の向上に資するFDフォーラムを年に複数回実施する。 | E50: 3 | F50: 10 | G50: ・ ファカルティ・ディベロップメント（FD活動を授業の工夫内容等に関する内容のものを含めて定期的に開催する（月１回程度）。 ・アクティブラーニングやPBL、ルーブリック評価などについての研修会、勉強会を実施する。（2018年度にかなり集中的におこなったので、2019年度は年間１回程度）アクティブラーニングや PBL については、教員間の授業参観を含む多様な形で取り組みを増進するよう努める。 ・授業評価アンケート結果及びリフレクションペーパーを学生に公表することで授業改善に努める。科目ごとに整理して、教員に配付することで、さらなる授業改善につなげる。また、教学システムの導入に伴い、授業評価アンケートのWeb化及びアンケート項目の見直しも検討する。 ・学生から評価の高い授業について、担当教員の授業参観を実施し、他の教員が参観する。以前に実施した時より参加者、参観授業の数が増えるよう教員側のスケジュールを再調整する。 ・実践教育専門委員会での2018年度の議論のまとめと、地域経営学研究会のその後の進展も踏まえて、遅くとも2019年度後期には大学全体での方向づけについてFD委員会主催のフォーラムで話し合う。 | H50: ・ファカルティ・ディベロップメント（FD）活動として、「研究倫理講習、研究費不正防止、研究不正防止」「地域協働型実践教育研究のあり方」「科学研究費獲得、大学評価と研究活性化」「ポートフォリオの実施状況」「地域経営研究の情報交換」など年間10回の活動を行った。 ・教学情報システムを導入したことで、授業評価アンケートを全面的にWebアンケートに移行し、その結果に対して全教員がリフレクションペーパー（振り返りシート）を作成した。 ・指導技術等を学び合うことを目的に、全教員による授業参観を実施した。計14科目（交流観光政策論や交流居住論など）を教員が参観し、報告書を共有し、指導技術などの改善に取り組んだ。 ・地域協働型教育を実践する科目である「地域経営演習Ⅰ～Ⅳ」「地域経営研究Ⅰ・Ⅱ」の指導方法等を共有する場を設定し、演習状況や学生指導等に関し、意見交換を行い、改善に繋げた。 ・FDフォーラムにおいて、地域経営学の体系と展望等の内容で教員発表（副学長、各学科長）を行い、北近畿地域連携機構の今後の体制や大学の方向性、地域経営学・地域協働型教育研究のあり方等の討議を行い認識の共有を図った。 | I50: 3
B53: 8 | C53: ウ 内部質保証への取り組みの推進
C54: 自己点検・評価の実施及び外部評価の受審に向けた内部質保証への取り組みを推進する。 | D54: 【2016年度～2019年度の総括】 ・受審に向けた取り組みとして、カリキュラム・ポリシーの明確化と教育課程への反映をするため、2016年度に見直し作業を行い、2017年度からのカリキュラムを改定（カリキュラムは2019年度にも見直し作業を行い、2020年度にも再度改定）したほか、内部質保証の方針や教員組織の編成方針を作成した。 ・2016年から2017年にかけて認証評価機関である（公財）大学基準協会の評価を受審し、「適合」の認定を受けた。 ・2018年度以降は、2017年度に受審した証評価機関の評価結果等を踏まえた対応状況を点検及び検討した。 ・2019年度に自己点検・評価の体制を見直し、半期ごとに教育の成果や内容、実施体制になど、年度計画の進捗状況を点検し、点検結果を学内にフィードバックして年度計画の各取組を着実に達成するよう促す体制を取り、PDCAサイクルを構築した。 ・各分野の業務改善に活かすために2019年度からIR専門委員会を発足し、各部署から基礎データを収集した。 【2020年度・2021年度の見込】 ・2019年度から実施した自己点検・評価について、2020年度以降も実施し、その方法、効果等を検証し、点検・評価における客観性・妥当性を確保する。 | E54: 4 | F54: 11 | G54: ・自己点検評価委員会で毎年度の自己点検評価の方法等を検討する。 大学基準協会等の点検・評価項目、評価の視点、根拠資料を参考に本学としての点検・評価のシステムを検討する。 2020年度の年度計画、予算作成時（8月）に合わせて簡易な自己点検評価を実施することを目指す。 | H54: ・自己点検・評価の体制を見直し、半期ごとに教育の成果や内容、実施体制にするなど、年度計画の進捗状況を点検し、点検結果を学内にフィードバックして年度計画の各取組を着実に達成するよう促す体制を取り、PDCAサイクルを構築した。 ・認証評価機関である（公財）大学基準協会等の点検・評価項目と本学の中期目標、中期計画及び年度計画の対応表を作成して点検を実施した。ここで出た課題を受けて、第2期中期目標や中期計画では、認証評価機関の点検・評価項目と合致するよう取り組むことを確認した。 ・自己点検・評価委員会内にIR（Institutional Research）専門委員会を発足させ、教務、学生生活、教職員等の基礎データを収集・分析することにより、各分野の業務等の改善に活かすこととした。 | I54: 4
...

Sheet 【作成用】学部・学科等
B5: 大学 | C5: 学部 | D5: 学科 | E5: 入学定員 | G5: 編入学定員 | H5: 収容定員 | I5: 在籍学生数
B6: 福知山公立大学 | C6: 地域経営学部 | D6: 地域経営学科 | E6: 95人 | G6: 5人 | H6: 335人 | I6: 295人
D7: 医療福祉経営学科 | E7: 25人 | G7: 2人 | H7: 89人 | I7: 71人
C8: 計 | E8: 120人 | G8: 7人 | H8: 424人 | I8: 366人
B9: ※平成30年5月1日現在
C13: 学部 | D13: 学科 | E13: 1年 | G13: 2年 | H13: 3年 | I13: 4年 | J13: 計 | K13: 編入学 | L13: 収容定員
C14: 地域経営学部 | D14: 地域経営学科 | E14: 95 | G14: 95 | H14: 40 | I14: 30 | J14: =SUM(E14:I14) -> 260 | K14: 10 | L14: =J14+K14 -> 270
D15: 医療福祉経営学科 | E15: 25 | G15: 25 | H15: 10 | I15: 20 | J15: =SUM(E15:I15) -> 80 | K15: 4 | L15: =J15+K15 -> 84
C16: 計 | E16: =SUM(E14:E15) -> 120 | G16: =SUM(G14:G15) -> 120 | H16: =SUM(H14:H15) -> 50 | I16: =SUM(I14:I15) -> 50 | J16: =SUM(J14:J15) -> 340 | K16: =SUM(K14:K15) -> 14 | L16: =SUM(L14:L15) -> 354
I19: 単位：人
B20: 大学 | C20: 学部 | D20: 学科 | E20: 入学定員 | F20: 編入学定員 | G20: 収容定員 | H20: 現員
H21: 男 | I21: 女 | J21: 計
B22: 福知山公立大学 | C22: 地域経営学部 | D22: 地域経営学科 | E22: 95 | F22: 5 | G22: 335 | H22: 249 | I22: 122 | J22: 371
D23: 医療福祉経営学科 | E23: 25 | F23: 2 | G23: 89 | H23: 39 | I23: 59 | J23: 98
C24: 合計 | E24: 120 | F24: 7 | G24: 424 | H24: 288 | I24: 181 | J24: 469
B25: ※2019年5月1日現在
B28: 大学 | C28: 学部・研究科 | D28: 学科・専攻 | E28: 入学定員 | F28: 編入学定員 | G28: 収容定員 | H28: 現員
H29: 男 | I29: 女 | J29: 計
B30: 福知山公立大学 | C30: 地域経営学部 | D30: 地域経営学科 | E30: 75 | F30: 5 | G30: 310 | H30: 174 | I30: 177 | J30: =SUM(H30:I30) -> 351
D31: 医療福祉経営学科 | E31: 25 | F31: 2 | G31: 104 | H31: 39 | I31: 65 | J31: =SUM(H31:I31) -> 104
C32: 情報学部 | D32: 情報学科 | E32: 100 | F32: 2 | G32: 404 | H32: 316 | I32: 114 | J32: =SUM(H32:I32) -> 430
C33: 地域情報学研究科 | D33: 地域情報学専攻 | E33: 20 | G33: 40 | H33: 28 | I33: 3 | J33: =SUM(H33:I33) -> 31
C34: 合計 | E34: =SUM(E30:E33) -> 220 | F34: =SUM(F30:F33) -> 9 | G34: =SUM(G30:G33) -> 858 | H34: =SUM(H30:H33) -> 557 | I34: =SUM(I30:I33) -> 359 | J34: =SUM(H34:I34) -> 916

Sheet 【作成用】組織図（平成30年）
B3: 公立大学法人福知山公立大学 組織図
L5: 事務局
E6: 理事会選考会議
H7: 経営審議会 | M7: 総務企画・財務グループ
B9: 理事長（学長） | E9: 理事会 | N9: 企画戦略
H11: 教育研究審議会 | N11: 地域連携・協働
E13: 監事 | N13: 総務・人事
E15: 内部統制推進委員会 | N15: 財務
B18: 公立大学 | E18: 地域経営学部 | H18: 地域経営学科 | M18: 学務・学生支援グループ
H20: 医療福祉経営学科 | N20: 入試広報
N22: 学務
E24: 教授会 | I24: 入試委員会 | N24: 学生・キャリアサポート
I26: 教務委員会
E28: 自己点検・評価委員会 | I28: 学生委員会
E30: 広報委員会 | I30: キャリアサポート委員会
E32: SD委員会 | I32: FD委員会
E34: 衛生委員会
E36: 危機管理・人権・倫理委員会
E38: 国際交流センター委員会
E40: 研究費不正使用防止対策委員会
E42: 研究活動不正行為防止対策委員会
D44: 付属施設
E46: メディアセンター（図書館） | I46: メディアセンター委員会
E48: 北近畿地域連携センター | I48: 北近畿地域連携センター委員会
E50: 市民学習・キャリア支援センター | I50: 市民学習・キャリア支援センター委員会

Sheet 年度計画等（全体）
D1: 公立大学法人福知山公立大学中期計画・年度計画（平成31年度年度計画・平成30年度執行見込）
B3: 中期目標 | E3: 中期計画 | J3: 平成３１年度年度計画
B4: 前文
D5: 福知山公立大学は、京都府北部、兵庫県北部にまたがる丹波、丹後、但馬により形成される「三たん地域」の中央部にある福知山市に位置する北近畿地域唯一の４年制大学である。 人口60万人に達する北近畿地域は、豊かな自然、歴史・文化資源、特色ある産業や高次都市機能を備えているものの、人口減少や高齢化の進行、産業の衰退、雇用の減少、市街地の空洞化など、様々な課題が生じている。 特に、進学・就職による若者の都市部への流出は深刻であり、地域から貴重な人材と資産、活力が失われていることを意味する。 北近畿地域が人口減少・高齢化に伴う地域活力の減退からの脱却を図り、持続可能な地域社会の形成、地域が本来持つ素晴らしい資源を活かした地方創生を実現するためには、北近畿地域の行政機関や企業、金融機関、各種団体等と広域的に連携・協力して地域全体の活性化を図るとともに、地域の発展に寄与する人材を育成し、「地域で学び、地域で働く」という人材循環システムを構築しなければならない。 そのことが、北近畿地域のみならず、同様の問題を抱える日本全国の様々な地域を舞台に活躍する人材の育成及び広域的な人材循環にもつながる。 以上を踏まえ、公立大学法人福知山公立大学（以下、「法人」という。）の設立団体である福知山市は、福知山公立大学が福知山市のみでなく北近畿地域にとっての学びの拠点となり、地域住民の誇りとなる魅力あふれる大学となるよう、“教育のまち福知山「学びの拠点」基本構想”（以下、「基本構想」という。）に掲げる次の基本理念のもと、中期目標を定め、法人に指示するものである。 ○地域を愛し、地域のために働きたいと思える、地域の将来を担う人材育成拠点を構築する。 ○地域産業の振興と雇用創出による賑わいと地域活力にあふれ、若者が定住する魅力あるまちを生み出す産業振興拠点を構築する。 ○市民一人ひとりの自己実現を支援し、生涯にわたり学びを享受できる生涯学習拠点を構築する。
B6: 第１ 基本的な目標 | E6: 第１ 基本的な目標
C7: １ 基本理念・目的 | F7: １ 基本理念・目的
D8: 福知山公立大学の基本理念を、「市民の大学、地域のための大学、世界とともに歩む大学」とする。 この基本理念のもと、福知山公立大学は、総合的な知識と専門的な学術を深く教授研究するとともに、地域協働型教育研究を積極的に展開することにより、地域に根ざし、世界を視野に活躍できる高度な知識及び技能を有する人材を育成し、北近畿地域の持続可能な地域社会の形成と地方創生に寄与することを目的とする。 そのため、基本構想に基づき、様々な地域課題の調査研究の実践を通じて、地域の将来を担う人材を育成するとともに、地域住民の自己実現を支援する「学びの拠点」を構築し、世界に貢献する開かれた大学の実現を目指すものとする。 | I8: 福知山公立大学は、平成28年4月1日に学校法人成美学園成美大学から福知山市を設置者とする公立大学法人福知山公立大学として新たなスタートをきった。 基本理念を「市民の大学、地域のための大学、世界とともに歩む大学」とする本学は、日本で唯一の地域経営学部を有し、総合的な知識と専門的な学術を深く教授研究するとともに、地域協働型教育研究を積極的に展開することにより、地域に根ざし、世界を視野に活躍できる高度な知識及び技能を有する人材を育成し、北近畿地域をはじめとする地域における持続可能な社会の形成と地方創生に寄与することを目的とする。そのため、「学びの拠点」を構築し、世界を視野にかつ地域に開かれた大学のあるべき姿を追究する。 このような基本理念と目的を踏まえ、中期目標を実現するための具体的計画として中期計画を定める。
C9: ２ 目指すべき大学像 | F9: ２ 目指すべき大学像
D10: 福知山公立大学の基本理念・目的に基づき、目指すべき大学像を次のとおりとする。 （１） 地域社会を支え、地域社会に支えられる大学 （２） 持続可能な社会の創出に貢献する知の拠点大学 （３） 地域と世界をつなぐ、グローカリズム研究実践の拠点大学 | I10: 福知山公立大学の基本理念・目的に基づき、目指すべき大学像を次のとおりとする。 （１） 地域社会を支え、地域社会に支えられる大学 （２） 持続可能な社会の創出に貢献する知の拠点大学 （３） 地域と世界をつなぐ、グローカリズム研究実践の拠点大学
C11: ３ 育成する人材像 | F11: ３ 育成する人材像
